Workbook

Sheet Висновки
A1: Турнір з піклболу (ветерани): аналіз реєстрації та результатів
A2: Джерело: Pickleball_11_10_26.xlsx (3 групи: пари 1 і 2, «Американо» 3). Дані перенесено в таблиці Dim_Players, Fact_Matches, Dim_Teams; усі зведення рахуються формулами.
A4: Учасників | B4: Матчів | C4: Сер. різниця очок | D4: Матчів 11:0 | E4: Додано вручну, %
A5: =COUNTA(Dim_Players!G2:G51) -> 50 | B5: =COUNTA(Fact_Matches!A2:A49) -> 48 | C5: =AVERAGE(Fact_Matches!K2:K49) -> 7.5625 | D5: =COUNTIF(Fact_Matches!G2:G49,0)+COUNTIF(Fact_Matches!H2:H49,0) -> 10 | E5: =COUNTIF(Dim_Players!I2:I51,"Додано вручну")/COUNTA(Dim_Players!G2:G51) -> 0.22
A7: Склад і реєстрація
A8: - 50 учасників: Група 1 - 16 (8 пар), Група 2 - 28 (14 пар), Група 3 - 6 (індивідуально, «Американо»). Зіграно 48 матчів (16 / 26 / 6).
A9: - Найбільша категорія - «ветерани з невидимими травмами»: 23 людини (46%). Категорії «крісла колісні» (5) і «протези» (4) грають лише в Групі 1, і там кожну пару з гравцем на кріслі зібрано з гравцем іншої категорії (змішані пари).
A10: - Лише 39 із 50 записів прийшли через форму (78%); 11 людей додано вручну (без номера і часу), а 11 номерів реєстрації (20, 21, 23, 24, 25, 35, 39, 41, 44, 47, 48) у сітках відсутні. Схоже на заміни та відмови, але це варто перевірити.
A11: - Реєстрація тривала з 21.09 до 05.10. Перший день дав 10 із 39 заявок (26%), далі були хвилі 23.09, 26-27.09 і 04.10 (перед дедлайном). Найактивніші години: 18-21 (14 заявок, 36%) і 9-11 (11 заявок, 28%) - анонси краще ставити саме на ці вікна.
A13: Рівень матчів
A14: - Середня різниця очок: 8,2 у груповому етапі проти 5,7 у play-off. Тобто плей-оф значно рівніший.
A15: - 24 із 48 матчів (50%) завершились із різницею 9+ очок, 10 матчів - «сухі» 11:0, і 9 з них припадають на групи Групи 2 (половина всіх її групових матчів). Дві пари Групи 2 програли всі три гри з рахунком 0:33.
A16: - Близьких матчів (різниця до 3 очок): 3 з 36 у групах (8%) проти 4 з 12 у play-off (33%). Обидва фінали вирішились мінімально: 11:7 і 11:8.
A17: - Переможці пулів у першому колі play-off (1/2 у Групі 1, 1/4 у Групі 2) виграли лише 3 з 6 матчів проти пар, що посіли 2-ге місце. Вибірка мала, але груповий етап слабо передбачив плей-оф.
A19: Результати
A20: - Група 1: 1 місце - Довгань / Катеринич О. (фінал 11:7 з Бичков / Пархоменко), 3 місце - Рябошапко / Олейник.
... A29: - Сіяти пули за рівнем (хоча б 2-3 рівні), щоб не було 11:0 у половині матчів. Додати поле «категорія / рівень» і для ручних заявок. Фіксувати причину відмови і заміни, щоб заявки не «зникали».

Sheet Pivot_Реєстрація
A1: Pivot: реєстрація учасників
A2: Усі зведення нижче - живі формули (COUNTIFS) над таблицею Dim_Players. Реєстрації без часу (додані вручну) у часових зведеннях не враховуються.
A4: 1. Реєстрації за датами
A5: Дата | B5: Реєстрацій | C5: Накопичувально
A6: 46286 | B6: =COUNTIFS(Dim_Players!$J$2:$J$51,A6) -> 10 | C6: =SUM($B$6:B6) -> 10
A7: 46287 | B7: =COUNTIFS(Dim_Players!$J$2:$J$51,A7) -> 2 | C7: =SUM($B$6:B7) -> 12
A8: 46288 | B8: =COUNTIFS(Dim_Players!$J$2:$J$51,A8) -> 6 | C8: =SUM($B$6:B8) -> 18
A9: 46289 | B9: =COUNTIFS(Dim_Players!$J$2:$J$51,A9) -> 2 | C9: =SUM($B$6:B9) -> 20
A10: 46290 | B10: =COUNTIFS(Dim_Players!$J$2:$J$51,A10) -> 0 | C10: =SUM($B$6:B10) -> 20
A11: 46291 | B11: =COUNTIFS(Dim_Players!$J$2:$J$51,A11) -> 4 | C11: =SUM($B$6:B11) -> 24
A12: 46292 | B12: =COUNTIFS(Dim_Players!$J$2:$J$51,A12) -> 3 | C12: =SUM($B$6:B12) -> 27
A13: 46293 | B13: =COUNTIFS(Dim_Players!$J$2:$J$51,A13) -> 0 | C13: =SUM($B$6:B13) -> 27
A14: 46294 | B14: =COUNTIFS(Dim_Players!$J$2:$J$51,A14) -> 2 | C14: =SUM($B$6:B14) -> 29
A15: 46295 | B15: =COUNTIFS(Dim_Players!$J$2:$J$51,A15) -> 0 | C15: =SUM($B$6:B15) -> 29
A16: 46296 | B16: =COUNTIFS(Dim_Players!$J$2:$J$51,A16) -> 3 | C16: =SUM($B$6:B16) -> 32
A17: 46297 | B17: =COUNTIFS(Dim_Players!$J$2:$J$51,A17) -> 0 | C17: =SUM($B$6:B17) -> 32
... A20: 46300 | B20: =COUNTIFS(Dim_Players!$J$2:$J$51,A20) -> 1 | C20: =SUM($B$6:B20) -> 39
A21: Разом | B21: =SUM(B6:B20) -> 39
A24: 2. Категорія × турнір (кількість гравців)
A25: Категорія | B25: Група 1 | C25: Група 2 | D25: Група 3 | E25: Всього | F25: Частка
A26: Ветерани з невидимими травмами | B26: =COUNTIFS(Dim_Players!$H$2:$H$51,$A26,Dim_Players!$C$2:$C$51,B$25) -> 4 | C26: =COUNTIFS(Dim_Players!$H$2:$H$51,$A26,Dim_Players!$C$2:$C$51,C$25) -> 19 | D26: =COUNTIFS(Dim_Players!$H$2:$H$51,$A26,Dim_Players!$C$2:$C$51,D$25) -> 0 | E26: =SUM(B26:D26) -> 23 | F26: =E26/$E$32 -> 0.46
A27: Ветерани на кріслах колісних | B27: =COUNTIFS(Dim_Players!$H$2:$H$51,$A27,Dim_Players!$C$2:$C$51,B$25) -> 5 | C27: =COUNTIFS(Dim_Players!$H$2:$H$51,$A27,Dim_Players!$C$2:$C$51,C$25) -> 0 | D27: =COUNTIFS(Dim_Players!$H$2:$H$51,$A27,Dim_Players!$C$2:$C$51,D$25) -> 0 | E27: =SUM(B27:D27) -> 5 | F27: =E27/$E$32 -> 0.1
A28: Ветерани на протезах | B28: =COUNTIFS(Dim_Players!$H$2:$H$51,$A28,Dim_Players!$C$2:$C$51,B$25) -> 4 | C28: =COUNTIFS(Dim_Players!$H$2:$H$51,$A28,Dim_Players!$C$2:$C$51,C$25) -> 0 | D28: =COUNTIFS(Dim_Players!$H$2:$H$51,$A28,Dim_Players!$C$2:$C$51,D$25) -> 0 | E28: =SUM(B28:D28) -> 4 | F28: =E28/$E$32 -> 0.08
A29: Ветерани без поранень | B29: =COUNTIFS(Dim_Players!$H$2:$H$51,$A29,Dim_Players!$C$2:$C$51,B$25) -> 0 | C29: =COUNTIFS(Dim_Players!$H$2:$H$51,$A29,Dim_Players!$C$2:$C$51,C$25) -> 3 | D29: =COUNTIFS(Dim_Players!$H$2:$H$51,$A29,Dim_Players!$C$2:$C$51,D$25) -> 1 | E29: =SUM(B29:D29) -> 4 | F29: =E29/$E$32 -> 0.08
A30: Члени родин ветеранів | B30: =COUNTIFS(Dim_Players!$H$2:$H$51,$A30,Dim_Players!$C$2:$C$51,B$25) -> 0 | C30: =COUNTIFS(Dim_Players!$H$2:$H$51,$A30,Dim_Players!$C$2:$C$51,C$25) -> 0 | D30: =COUNTIFS(Dim_Players!$H$2:$H$51,$A30,Dim_Players!$C$2:$C$51,D$25) -> 4 | E30: =SUM(B30:D30) -> 4 | F30: =E30/$E$32 -> 0.08
A31: Не вказано | B31: =COUNTIFS(Dim_Players!$H$2:$H$51,$A31,Dim_Players!$C$2:$C$51,B$25) -> 3 | C31: =COUNTIFS(Dim_Players!$H$2:$H$51,$A31,Dim_Players!$C$2:$C$51,C$25) -> 6 | D31: =COUNTIFS(Dim_Players!$H$2:$H$51,$A31,Dim_Players!$C$2:$C$51,D$25) -> 1 | E31: =SUM(B31:D31) -> 10 | F31: =E31/$E$32 -> 0.2
A32: Разом | B32: =SUM(B26:B31) -> 16 | C32: =SUM(C26:C31) -> 28 | D32: =SUM(D26:D31) -> 6 | E32: =SUM(E26:E31) -> 50 | F32: =E32/E32 -> 1
A36: 3. Година реєстрації
A37: Година | B37: Реєстрацій
A38: 6 | B38: =COUNTIFS(Dim_Players!$K$2:$K$51,A38) -> 1
A39: 7 | B39: =COUNTIFS(Dim_Players!$K$2:$K$51,A39) -> 0
A40: 8 | B40: =COUNTIFS(Dim_Players!$K$2:$K$51,A40) -> 1
A41: 9 | B41: =COUNTIFS(Dim_Players!$K$2:$K$51,A41) -> 5
A42: 10 | B42: =COUNTIFS(Dim_Players!$K$2:$K$51,A42) -> 3
A43: 11 | B43: =COUNTIFS(Dim_Players!$K$2:$K$51,A43) -> 3
A44: 12 | B44: =COUNTIFS(Dim_Players!$K$2:$K$51,A44) -> 2
A45: 13 | B45: =COUNTIFS(Dim_Players!$K$2:$K$51,A45) -> 3
A46: 14 | B46: =COUNTIFS(Dim_Players!$K$2:$K$51,A46) -> 2
A47: 15 | B47: =COUNTIFS(Dim_Players!$K$2:$K$51,A47) -> 1
A48: 16 | B48: =COUNTIFS(Dim_Players!$K$2:$K$51,A48) -> 3
...

Sheet Pivot_Матчі
A1: Pivot: матчі та конкурентність
A2: Джерело: таблиця Fact_Matches (48 матчів). Різниця очок = модуль різниці рахунку; "близькі" - різниця до 3 очок включно; "розгроми" - від 9.
A4: 1. Турнір × етап
A5: Турнір / етап | B5: Турнір | C5: Етап | D5: Матчів | E5: Сер. різниця | F5: Сер. сума очок | G5: Матчів 11:0 | H5: Близьких (≤3) | I5: Розгромів (≥9)
A6: Г1 групи | B6: Група 1 | C6: Груповий етап | D6: =COUNTIFS(Fact_Matches!$B$2:$B$49,$B6,Fact_Matches!$C$2:$C$49,$C6) -> 12 | E6: =AVERAGEIFS(Fact_Matches!$K$2:$K$49,Fact_Matches!$B$2:$B$49,$B6,Fact_Matches!$C$2:$C$49,$C6) -> 7.1666667 | F6: =AVERAGEIFS(Fact_Matches!$L$2:$L$49,Fact_Matches!$B$2:$B$49,$B6,Fact_Matches!$C$2:$C$49,$C6) -> 14.833333 | G6: =COUNTIFS(Fact_Matches!$B$2:$B$49,$B6,Fact_Matches!$C$2:$C$49,$C6,Fact_Matches!$G$2:$G$49,0)+COUNTIFS(Fact_Matches!$B$2:$B$49,$B6,Fact_Matches!$C$2:$C$49,$C6,Fact_Matches!$H$2:$H$49,0) -> 0 | H6: =COUNTIFS(Fact_Matches!$B$2:$B$49,$B6,Fact_Matches!$C$2:$C$49,$C6,Fact_Matches!$K$2:$K$49,"<=3") -> 2 | I6: =COUNTIFS(Fact_Matches!$B$2:$B$49,$B6,Fact_Matches!$C$2:$C$49,$C6,Fact_Matches!$K$2:$K$49,">=9") -> 5
A7: Г1 play-off | B7: Група 1 | C7: Play-off | D7: =COUNTIFS(Fact_Matches!$B$2:$B$49,$B7,Fact_Matches!$C$2:$C$49,$C7) -> 4 | E7: =AVERAGEIFS(Fact_Matches!$K$2:$K$49,Fact_Matches!$B$2:$B$49,$B7,Fact_Matches!$C$2:$C$49,$C7) -> 6.25 | F7: =AVERAGEIFS(Fact_Matches!$L$2:$L$49,Fact_Matches!$B$2:$B$49,$B7,Fact_Matches!$C$2:$C$49,$C7) -> 15.75 | G7: =COUNTIFS(Fact_Matches!$B$2:$B$49,$B7,Fact_Matches!$C$2:$C$49,$C7,Fact_Matches!$G$2:$G$49,0)+COUNTIFS(Fact_Matches!$B$2:$B$49,$B7,Fact_Matches!$C$2:$C$49,$C7,Fact_Matches!$H$2:$H$49,0) -> 0 | H7: =COUNTIFS(Fact_Matches!$B$2:$B$49,$B7,Fact_Matches!$C$2:$C$49,$C7,Fact_Matches!$K$2:$K$49,"<=3") -> 1 | I7: =COUNTIFS(Fact_Matches!$B$2:$B$49,$B7,Fact_Matches!$C$2:$C$49,$C7,Fact_Matches!$K$2:$K$49,">=9") -> 2
A8: Г2 групи | B8: Група 2 | C8: Груповий етап | D8: =COUNTIFS(Fact_Matches!$B$2:$B$49,$B8,Fact_Matches!$C$2:$C$49,$C8) -> 18 | E8: =AVERAGEIFS(Fact_Matches!$K$2:$K$49,Fact_Matches!$B$2:$B$49,$B8,Fact_Matches!$C$2:$C$49,$C8) -> 8.8333333 | F8: =AVERAGEIFS(Fact_Matches!$L$2:$L$49,Fact_Matches!$B$2:$B$49,$B8,Fact_Matches!$C$2:$C$49,$C8) -> 13.388889 | G8: =COUNTIFS(Fact_Matches!$B$2:$B$49,$B8,Fact_Matches!$C$2:$C$49,$C8,Fact_Matches!$G$2:$G$49,0)+COUNTIFS(Fact_Matches!$B$2:$B$49,$B8,Fact_Matches!$C$2:$C$49,$C8,Fact_Matches!$H$2:$H$49,0) -> 9 | H8: =COUNTIFS(Fact_Matches!$B$2:$B$49,$B8,Fact_Matches!$C$2:$C$49,$C8,Fact_Matches!$K$2:$K$49,"<=3") -> 1 | I8: =COUNTIFS(Fact_Matches!$B$2:$B$49,$B8,Fact_Matches!$C$2:$C$49,$C8,Fact_Matches!$K$2:$K$49,">=9") -> 12
A9: Г2 play-off | B9: Група 2 | C9: Play-off | D9: =COUNTIFS(Fact_Matches!$B$2:$B$49,$B9,Fact_Matches!$C$2:$C$49,$C9) -> 8 | E9: =AVERAGEIFS(Fact_Matches!$K$2:$K$49,Fact_Matches!$B$2:$B$49,$B9,Fact_Matches!$C$2:$C$49,$C9) -> 5.375 | F9: =AVERAGEIFS(Fact_Matches!$L$2:$L$49,Fact_Matches!$B$2:$B$49,$B9,Fact_Matches!$C$2:$C$49,$C9) -> 16.625 | G9: =COUNTIFS(Fact_Matches!$B$2:$B$49,$B9,Fact_Matches!$C$2:$C$49,$C9,Fact_Matches!$G$2:$G$49,0)+COUNTIFS(Fact_Matches!$B$2:$B$49,$B9,Fact_Matches!$C$2:$C$49,$C9,Fact_Matches!$H$2:$H$49,0) -> 0 | H9: =COUNTIFS(Fact_Matches!$B$2:$B$49,$B9,Fact_Matches!$C$2:$C$49,$C9,Fact_Matches!$K$2:$K$49,"<=3") -> 3 | I9: =COUNTIFS(Fact_Matches!$B$2:$B$49,$B9,Fact_Matches!$C$2:$C$49,$C9,Fact_Matches!$K$2:$K$49,">=9") -> 2
A10: Г3 американо | B10: Група 3 | C10: Груповий етап | D10: =COUNTIFS(Fact_Matches!$B$2:$B$49,$B10,Fact_Matches!$C$2:$C$49,$C10) -> 6 | E10: =AVERAGEIFS(Fact_Matches!$K$2:$K$49,Fact_Matches!$B$2:$B$49,$B10,Fact_Matches!$C$2:$C$49,$C10) -> 8.3333333 | F10: =AVERAGEIFS(Fact_Matches!$L$2:$L$49,Fact_Matches!$B$2:$B$49,$B10,Fact_Matches!$C$2:$C$49,$C10) -> 13.666667 | G10: =COUNTIFS(Fact_Matches!$B$2:$B$49,$B10,Fact_Matches!$C$2:$C$49,$C10,Fact_Matches!$G$2:$G$49,0)+COUNTIFS(Fact_Matches!$B$2:$B$49,$B10,Fact_Matches!$C$2:$C$49,$C10,Fact_Matches!$H$2:$H$49,0) -> 1 | H10: =COUNTIFS(Fact_Matches!$B$2:$B$49,$B10,Fact_Matches!$C$2:$C$49,$C10,Fact_Matches!$K$2:$K$49,"<=3") -> 0 | I10: =COUNTIFS(Fact_Matches!$B$2:$B$49,$B10,Fact_Matches!$C$2:$C$49,$C10,Fact_Matches!$K$2:$K$49,">=9") -> 3
A11: Разом | D11: =SUM(D6:D10) -> 48 | E11: =AVERAGE(Fact_Matches!$K$2:$K$49) -> 7.5625 | F11: =AVERAGE(Fact_Matches!$L$2:$L$49) -> 14.520833 | G11: =SUM(G6:G10) -> 10 | H11: =SUM(H6:H10) -> 7 | I11: =SUM(I6:I10) -> 24
A14: 2. Розподіл різниці очок
A15: Різниця очок | B15: Від | C15: До | D15: Груповий етап | E15: Play-off | F15: Разом
A16: 1-2 | B16: 1 | C16: 2 | D16: =COUNTIFS(Fact_Matches!$K$2:$K$49,">="&$B16,Fact_Matches!$K$2:$K$49,"<="&$C16,Fact_Matches!$C$2:$C$49,"Груповий етап") -> 2 | E16: =COUNTIFS(Fact_Matches!$K$2:$K$49,">="&$B16,Fact_Matches!$K$2:$K$49,"<="&$C16,Fact_Matches!$C$2:$C$49,"Play-off") -> 0 | F16: =D16+E16 -> 2
A17: 3-4 | B17: 3 | C17: 4 | D17: =COUNTIFS(Fact_Matches!$K$2:$K$49,">="&$B17,Fact_Matches!$K$2:$K$49,"<="&$C17,Fact_Matches!$C$2:$C$49,"Груповий етап") -> 2 | E17: =COUNTIFS(Fact_Matches!$K$2:$K$49,">="&$B17,Fact_Matches!$K$2:$K$49,"<="&$C17,Fact_Matches!$C$2:$C$49,"Play-off") -> 6 | F17: =D17+E17 -> 8
A18: 5-6 | B18: 5 | C18: 6 | D18: =COUNTIFS(Fact_Matches!$K$2:$K$49,">="&$B18,Fact_Matches!$K$2:$K$49,"<="&$C18,Fact_Matches!$C$2:$C$49,"Груповий етап") -> 4 | E18: =COUNTIFS(Fact_Matches!$K$2:$K$49,">="&$B18,Fact_Matches!$K$2:$K$49,"<="&$C18,Fact_Matches!$C$2:$C$49,"Play-off") -> 2 | F18: =D18+E18 -> 6
A19: 7-8 | B19: 7 | C19: 8 | D19: =COUNTIFS(Fact_Matches!$K$2:$K$49,">="&$B19,Fact_Matches!$K$2:$K$49,"<="&$C19,Fact_Matches!$C$2:$C$49,"Груповий етап") -> 8 | E19: =COUNTIFS(Fact_Matches!$K$2:$K$49,">="&$B19,Fact_Matches!$K$2:$K$49,"<="&$C19,Fact_Matches!$C$2:$C$49,"Play-off") -> 0 | F19: =D19+E19 -> 8
A20: 9-10 | B20: 9 | C20: 10 | D20: =COUNTIFS(Fact_Matches!$K$2:$K$49,">="&$B20,Fact_Matches!$K$2:$K$49,"<="&$C20,Fact_Matches!$C$2:$C$49,"Груповий етап") -> 10 | E20: =COUNTIFS(Fact_Matches!$K$2:$K$49,">="&$B20,Fact_Matches!$K$2:$K$49,"<="&$C20,Fact_Matches!$C$2:$C$49,"Play-off") -> 4 | F20: =D20+E20 -> 14
A21: 11 (суха) | B21: 11 | C21: 11 | D21: =COUNTIFS(Fact_Matches!$K$2:$K$49,">="&$B21,Fact_Matches!$K$2:$K$49,"<="&$C21,Fact_Matches!$C$2:$C$49,"Груповий етап") -> 10 | E21: =COUNTIFS(Fact_Matches!$K$2:$K$49,">="&$B21,Fact_Matches!$K$2:$K$49,"<="&$C21,Fact_Matches!$C$2:$C$49,"Play-off") -> 0 | F21: =D21+E21 -> 10
A22: Разом | D22: =SUM(D16:D21) -> 36 | E22: =SUM(E16:E21) -> 12 | F22: =SUM(F16:F21) -> 48
A25: 3. Груповий етап проти play-off (усі турніри)
A26: Етап | B26: Матчів | C26: Сер. різниця | D26: Сер. сума очок | E26: Близьких, %
A27: Груповий етап | B27: =COUNTIFS(Fact_Matches!$C$2:$C$49,A27) -> 36 | C27: =AVERAGEIFS(Fact_Matches!$K$2:$K$49,Fact_Matches!$C$2:$C$49,A27) -> 8.1944444 | D27: =AVERAGEIFS(Fact_Matches!$L$2:$L$49,Fact_Matches!$C$2:$C$49,A27) -> 13.916667 | E27: =COUNTIFS(Fact_Matches!$C$2:$C$49,A27,Fact_Matches!$K$2:$K$49,"<=3")/B27 -> 0.083333333
A28: Play-off | B28: =COUNTIFS(Fact_Matches!$C$2:$C$49,A28) -> 12 | C28: =AVERAGEIFS(Fact_Matches!$K$2:$K$49,Fact_Matches!$C$2:$C$49,A28) -> 5.6666667 | D28: =AVERAGEIFS(Fact_Matches!$L$2:$L$49,Fact_Matches!$C$2:$C$49,A28) -> 16.333333 | E28: =COUNTIFS(Fact_Matches!$C$2:$C$49,A28,Fact_Matches!$K$2:$K$49,"<=3")/B28 -> 0.33333333

Sheet Американо
A1: Група 3: формат «Американо» (індивідуальний залік)
A2: Пари змінюються щомісяця матчу; кожна гравчиня зіграла по 4 з 6 матчів. Формули шукають прізвище в назві пари (Fact_Matches, Tournament = "Група 3").
A4: Гравчиня | B4: Ігор | C4: Перемог | D4: Поразок | E4: Очки (+) | F4: Очки (-) | G4: Різниця | H4: Місце
A5: Крівонос Г. | B5: =COUNTIFS(Fact_Matches!$B$2:$B$49,"Група 3",Fact_Matches!$F$2:$F$49,"*"&$A5&"*")+COUNTIFS(Fact_Matches!$B$2:$B$49,"Група 3",Fact_Matches!$I$2:$I$49,"*"&$A5&"*") -> 4 | C5: =COUNTIFS(Fact_Matches!$B$2:$B$49,"Група 3",Fact_Matches!$J$2:$J$49,"*"&$A5&"*") -> 4 | D5: =B5-C5 -> 0 | E5: =SUMIFS(Fact_Matches!$G$2:$G$49,Fact_Matches!$B$2:$B$49,"Група 3",Fact_Matches!$F$2:$F$49,"*"&$A5&"*")+SUMIFS(Fact_Matches!$H$2:$H$49,Fact_Matches!$B$2:$B$49,"Група 3",Fact_Matches!$I$2:$I$49,"*"&$A5&"*") -> 44 | F5: =SUMIFS(Fact_Matches!$H$2:$H$49,Fact_Matches!$B$2:$B$49,"Група 3",Fact_Matches!$F$2:$F$49,"*"&$A5&"*")+SUMIFS(Fact_Matches!$G$2:$G$49,Fact_Matches!$B$2:$B$49,"Група 3",Fact_Matches!$I$2:$I$49,"*"&$A5&"*") -> 10 | G5: =E5-F5 -> 34 | H5: =1+COUNTIF($C$5:$C$10,">"&C5)+SUMPRODUCT(($C$5:$C$10=C5)*($G$5:$G$10>G5)) -> 1
A6: Катеринич І. | B6: =COUNTIFS(Fact_Matches!$B$2:$B$49,"Група 3",Fact_Matches!$F$2:$F$49,"*"&$A6&"*")+COUNTIFS(Fact_Matches!$B$2:$B$49,"Група 3",Fact_Matches!$I$2:$I$49,"*"&$A6&"*") -> 4 | C6: =COUNTIFS(Fact_Matches!$B$2:$B$49,"Група 3",Fact_Matches!$J$2:$J$49,"*"&$A6&"*") -> 3 | D6: =B6-C6 -> 1 | E6: =SUMIFS(Fact_Matches!$G$2:$G$49,Fact_Matches!$B$2:$B$49,"Група 3",Fact_Matches!$F$2:$F$49,"*"&$A6&"*")+SUMIFS(Fact_Matches!$H$2:$H$49,Fact_Matches!$B$2:$B$49,"Група 3",Fact_Matches!$I$2:$I$49,"*"&$A6&"*") -> 34 | F6: =SUMIFS(Fact_Matches!$H$2:$H$49,Fact_Matches!$B$2:$B$49,"Група 3",Fact_Matches!$F$2:$F$49,"*"&$A6&"*")+SUMIFS(Fact_Matches!$G$2:$G$49,Fact_Matches!$B$2:$B$49,"Група 3",Fact_Matches!$I$2:$I$49,"*"&$A6&"*") -> 23 | G6: =E6-F6 -> 11 | H6: =1+COUNTIF($C$5:$C$10,">"&C6)+SUMPRODUCT(($C$5:$C$10=C6)*($G$5:$G$10>G6)) -> 2
A7: Концева Е. | B7: =COUNTIFS(Fact_Matches!$B$2:$B$49,"Група 3",Fact_Matches!$F$2:$F$49,"*"&$A7&"*")+COUNTIFS(Fact_Matches!$B$2:$B$49,"Група 3",Fact_Matches!$I$2:$I$49,"*"&$A7&"*") -> 4 | C7: =COUNTIFS(Fact_Matches!$B$2:$B$49,"Група 3",Fact_Matches!$J$2:$J$49,"*"&$A7&"*") -> 2 | D7: =B7-C7 -> 2 | E7: =SUMIFS(Fact_Matches!$G$2:$G$49,Fact_Matches!$B$2:$B$49,"Група 3",Fact_Matches!$F$2:$F$49,"*"&$A7&"*")+SUMIFS(Fact_Matches!$H$2:$H$49,Fact_Matches!$B$2:$B$49,"Група 3",Fact_Matches!$I$2:$I$49,"*"&$A7&"*") -> 30 | F7: =SUMIFS(Fact_Matches!$H$2:$H$49,Fact_Matches!$B$2:$B$49,"Група 3",Fact_Matches!$F$2:$F$49,"*"&$A7&"*")+SUMIFS(Fact_Matches!$G$2:$G$49,Fact_Matches!$B$2:$B$49,"Група 3",Fact_Matches!$I$2:$I$49,"*"&$A7&"*") -> 29 | G7: =E7-F7 -> 1 | H7: =1+COUNTIF($C$5:$C$10,">"&C7)+SUMPRODUCT(($C$5:$C$10=C7)*($G$5:$G$10>G7)) -> 3
A8: Котліна В. | B8: =COUNTIFS(Fact_Matches!$B$2:$B$49,"Група 3",Fact_Matches!$F$2:$F$49,"*"&$A8&"*")+COUNTIFS(Fact_Matches!$B$2:$B$49,"Група 3",Fact_Matches!$I$2:$I$49,"*"&$A8&"*") -> 4 | C8: =COUNTIFS(Fact_Matches!$B$2:$B$49,"Група 3",Fact_Matches!$J$2:$J$49,"*"&$A8&"*") -> 2 | D8: =B8-C8 -> 2 | E8: =SUMIFS(Fact_Matches!$G$2:$G$49,Fact_Matches!$B$2:$B$49,"Група 3",Fact_Matches!$F$2:$F$49,"*"&$A8&"*")+SUMIFS(Fact_Matches!$H$2:$H$49,Fact_Matches!$B$2:$B$49,"Група 3",Fact_Matches!$I$2:$I$49,"*"&$A8&"*") -> 25 | F8: =SUMIFS(Fact_Matches!$H$2:$H$49,Fact_Matches!$B$2:$B$49,"Група 3",Fact_Matches!$F$2:$F$49,"*"&$A8&"*")+SUMIFS(Fact_Matches!$G$2:$G$49,Fact_Matches!$B$2:$B$49,"Група 3",Fact_Matches!$I$2:$I$49,"*"&$A8&"*") -> 25 | G8: =E8-F8 -> 0 | H8: =1+COUNTIF($C$5:$C$10,">"&C8)+SUMPRODUCT(($C$5:$C$10=C8)*($G$5:$G$10>G8)) -> 4
A9: Папурова А. | B9: =COUNTIFS(Fact_Matches!$B$2:$B$49,"Група 3",Fact_Matches!$F$2:$F$49,"*"&$A9&"*")+COUNTIFS(Fact_Matches!$B$2:$B$49,"Група 3",Fact_Matches!$I$2:$I$49,"*"&$A9&"*") -> 4 | C9: =COUNTIFS(Fact_Matches!$B$2:$B$49,"Група 3",Fact_Matches!$J$2:$J$49,"*"&$A9&"*") -> 1 | D9: =B9-C9 -> 3 | E9: =SUMIFS(Fact_Matches!$G$2:$G$49,Fact_Matches!$B$2:$B$49,"Група 3",Fact_Matches!$F$2:$F$49,"*"&$A9&"*")+SUMIFS(Fact_Matches!$H$2:$H$49,Fact_Matches!$B$2:$B$49,"Група 3",Fact_Matches!$I$2:$I$49,"*"&$A9&"*") -> 24 | F9: =SUMIFS(Fact_Matches!$H$2:$H$49,Fact_Matches!$B$2:$B$49,"Група 3",Fact_Matches!$F$2:$F$49,"*"&$A9&"*")+SUMIFS(Fact_Matches!$G$2:$G$49,Fact_Matches!$B$2:$B$49,"Група 3",Fact_Matches!$I$2:$I$49,"*"&$A9&"*") -> 33 | G9: =E9-F9 -> -9 | H9: =1+COUNTIF($C$5:$C$10,">"&C9)+SUMPRODUCT(($C$5:$C$10=C9)*($G$5:$G$10>G9)) -> 5
A10: Ільїна Н. | B10: =COUNTIFS(Fact_Matches!$B$2:$B$49,"Група 3",Fact_Matches!$F$2:$F$49,"*"&$A10&"*")+COUNTIFS(Fact_Matches!$B$2:$B$49,"Група 3",Fact_Matches!$I$2:$I$49,"*"&$A10&"*") -> 4 | C10: =COUNTIFS(Fact_Matches!$B$2:$B$49,"Група 3",Fact_Matches!$J$2:$J$49,"*"&$A10&"*") -> 0 | D10: =B10-C10 -> 4 | E10: =SUMIFS(Fact_Matches!$G$2:$G$49,Fact_Matches!$B$2:$B$49,"Група 3",Fact_Matches!$F$2:$F$49,"*"&$A10&"*")+SUMIFS(Fact_Matches!$H$2:$H$49,Fact_Matches!$B$2:$B$49,"Група 3",Fact_Matches!$I$2:$I$49,"*"&$A10&"*") -> 7 | F10: =SUMIFS(Fact_Matches!$H$2:$H$49,Fact_Matches!$B$2:$B$49,"Група 3",Fact_Matches!$F$2:$F$49,"*"&$A10&"*")+SUMIFS(Fact_Matches!$G$2:$G$49,Fact_Matches!$B$2:$B$49,"Група 3",Fact_Matches!$I$2:$I$49,"*"&$A10&"*") -> 44 | G10: =E10-F10 -> -37 | H10: =1+COUNTIF($C$5:$C$10,">"&C10)+SUMPRODUCT(($C$5:$C$10=C10)*($G$5:$G$10>G10)) -> 6

Sheet Dim_Teams
A1: Tournament | B1: TeamNo | C1: Team | D1: Players | E1: Pool | F1: Games | G1: Wins | H1: Losses | I1: PointsFor | J1: PointsAgainst | K1: Diff | L1: WinRate | M1: Result | O1: Різниця очок по командах (усі матчі, Групи 1 і 2)
A2: Група 2 | B2: 2 | C2: Г2-Т2 Салабай / Шульга | D2: Салабай / Шульга | E2: Пул C | F2: =COUNTIF(Fact_Matches!$F$2:$F$49,C2)+COUNTIF(Fact_Matches!$I$2:$I$49,C2) -> 5 | G2: =COUNTIF(Fact_Matches!$J$2:$J$49,C2) -> 5 | H2: =F2-G2 -> 0 | I2: =SUMIF(Fact_Matches!$F$2:$F$49,C2,Fact_Matches!$G$2:$G$49)+SUMIF(Fact_Matches!$I$2:$I$49,C2,Fact_Matches!$H$2:$H$49) -> 55 | J2: =SUMIF(Fact_Matches!$F$2:$F$49,C2,Fact_Matches!$H$2:$H$49)+SUMIF(Fact_Matches!$I$2:$I$49,C2,Fact_Matches!$G$2:$G$49) -> 22 | K2: =I2-J2 -> 33 | L2: =IF(F2=0,0,G2/F2) -> 1 | M2: 1 місце
A3: Група 1 | B3: 1 | C3: Г1-Т1 Рябошапко / Олейник | D3: Рябошапко / Олейник | E3: Пул A | F3: =COUNTIF(Fact_Matches!$F$2:$F$49,C3)+COUNTIF(Fact_Matches!$I$2:$I$49,C3) -> 5 | G3: =COUNTIF(Fact_Matches!$J$2:$J$49,C3) -> 4 | H3: =F3-G3 -> 1 | I3: =SUMIF(Fact_Matches!$F$2:$F$49,C3,Fact_Matches!$G$2:$G$49)+SUMIF(Fact_Matches!$I$2:$I$49,C3,Fact_Matches!$H$2:$H$49) -> 52 | J3: =SUMIF(Fact_Matches!$F$2:$F$49,C3,Fact_Matches!$H$2:$H$49)+SUMIF(Fact_Matches!$I$2:$I$49,C3,Fact_Matches!$G$2:$G$49) -> 20 | K3: =I3-J3 -> 32 | L3: =IF(F3=0,0,G3/F3) -> 0.8 | M3: 3 місце
A4: Група 2 | B4: 1 | C4: Г2-Т1 Сторожук / Нестерчук | D4: Сторожук / Нестерчук | E4: Пул D | F4: =COUNTIF(Fact_Matches!$F$2:$F$49,C4)+COUNTIF(Fact_Matches!$I$2:$I$49,C4) -> 5 | G4: =COUNTIF(Fact_Matches!$J$2:$J$49,C4) -> 4 | H4: =F4-G4 -> 1 | I4: =SUMIF(Fact_Matches!$F$2:$F$49,C4,Fact_Matches!$G$2:$G$49)+SUMIF(Fact_Matches!$I$2:$I$49,C4,Fact_Matches!$H$2:$H$49) -> 52 | J4: =SUMIF(Fact_Matches!$F$2:$F$49,C4,Fact_Matches!$H$2:$H$49)+SUMIF(Fact_Matches!$I$2:$I$49,C4,Fact_Matches!$G$2:$G$49) -> 25 | K4: =I4-J4 -> 27 | L4: =IF(F4=0,0,G4/F4) -> 0.8 | M4: 2 місце
A5: Група 2 | B5: 4 | C5: Г2-Т4 Тарарака / Татаров | D5: Тарарака / Татаров | E5: Пул B | F5: =COUNTIF(Fact_Matches!$F$2:$F$49,C5)+COUNTIF(Fact_Matches!$I$2:$I$49,C5) -> 6 | G5: =COUNTIF(Fact_Matches!$J$2:$J$49,C5) -> 4 | H5: =F5-G5 -> 2 | I5: =SUMIF(Fact_Matches!$F$2:$F$49,C5,Fact_Matches!$G$2:$G$49)+SUMIF(Fact_Matches!$I$2:$I$49,C5,Fact_Matches!$H$2:$H$49) -> 62 | J5: =SUMIF(Fact_Matches!$F$2:$F$49,C5,Fact_Matches!$H$2:$H$49)+SUMIF(Fact_Matches!$I$2:$I$49,C5,Fact_Matches!$G$2:$G$49) -> 37 | K5: =I5-J5 -> 25 | L5: =IF(F5=0,0,G5/F5) -> 0.66666667 | M5: 3 місце
A6: Група 1 | B6: 6 | C6: Г1-Т6 Довгань / Катеринич О. | D6: Довгань / Катеринич О. | E6: Пул B | F6: =COUNTIF(Fact_Matches!$F$2:$F$49,C6)+COUNTIF(Fact_Matches!$I$2:$I$49,C6) -> 5 | G6: =COUNTIF(Fact_Matches!$J$2:$J$49,C6) -> 4 | H6: =F6-G6 -> 1 | I6: =SUMIF(Fact_Matches!$F$2:$F$49,C6,Fact_Matches!$G$2:$G$49)+SUMIF(Fact_Matches!$I$2:$I$49,C6,Fact_Matches!$H$2:$H$49) -> 52 | J6: =SUMIF(Fact_Matches!$F$2:$F$49,C6,Fact_Matches!$H$2:$H$49)+SUMIF(Fact_Matches!$I$2:$I$49,C6,Fact_Matches!$G$2:$G$49) -> 28 | K6: =I6-J6 -> 24 | L6: =IF(F6=0,0,G6/F6) -> 0.8 | M6: 1 місце
A7: Група 2 | B7: 3 | C7: Г2-Т3 Концевой / Парфенюк | D7: Концевой / Парфенюк | E7: Пул A | F7: =COUNTIF(Fact_Matches!$F$2:$F$49,C7)+COUNTIF(Fact_Matches!$I$2:$I$49,C7) -> 4 | G7: =COUNTIF(Fact_Matches!$J$2:$J$49,C7) -> 3 | H7: =F7-G7 -> 1 | I7: =SUMIF(Fact_Matches!$F$2:$F$49,C7,Fact_Matches!$G$2:$G$49)+SUMIF(Fact_Matches!$I$2:$I$49,C7,Fact_Matches!$H$2:$H$49) -> 41 | J7: =SUMIF(Fact_Matches!$F$2:$F$49,C7,Fact_Matches!$H$2:$H$49)+SUMIF(Fact_Matches!$I$2:$I$49,C7,Fact_Matches!$G$2:$G$49) -> 21 | K7: =I7-J7 -> 20 | L7: =IF(F7=0,0,G7/F7) -> 0.75 | M7: 1/4 фіналу
A8: Група 2 | B8: 7 | C8: Г2-Т7 Орєшин / Грибонос | D8: Орєшин / Грибонос | E8: Пул B | F8: =COUNTIF(Fact_Matches!$F$2:$F$49,C8)+COUNTIF(Fact_Matches!$I$2:$I$49,C8) -> 4 | G8: =COUNTIF(Fact_Matches!$J$2:$J$49,C8) -> 3 | H8: =F8-G8 -> 1 | I8: =SUMIF(Fact_Matches!$F$2:$F$49,C8,Fact_Matches!$G$2:$G$49)+SUMIF(Fact_Matches!$I$2:$I$49,C8,Fact_Matches!$H$2:$H$49) -> 43 | J8: =SUMIF(Fact_Matches!$F$2:$F$49,C8,Fact_Matches!$H$2:$H$49)+SUMIF(Fact_Matches!$I$2:$I$49,C8,Fact_Matches!$G$2:$G$49) -> 26 | K8: =I8-J8 -> 17 | L8: =IF(F8=0,0,G8/F8) -> 0.75 | M8: 1/4 фіналу
A9: Група 2 | B9: 13 | C9: Г2-Т13 Фещук / Гиряк | D9: Фещук / Гиряк | E9: Пул A | F9: =COUNTIF(Fact_Matches!$F$2:$F$49,C9)+COUNTIF(Fact_Matches!$I$2:$I$49,C9) -> 6 | G9: =COUNTIF(Fact_Matches!$J$2:$J$49,C9) -> 3 | H9: =F9-G9 -> 3 | I9: =SUMIF(Fact_Matches!$F$2:$F$49,C9,Fact_Matches!$G$2:$G$49)+SUMIF(Fact_Matches!$I$2:$I$49,C9,Fact_Matches!$H$2:$H$49) -> 50 | J9: =SUMIF(Fact_Matches!$F$2:$F$49,C9,Fact_Matches!$H$2:$H$49)+SUMIF(Fact_Matches!$I$2:$I$49,C9,Fact_Matches!$G$2:$G$49) -> 41 | K9: =I9-J9 -> 9 | L9: =IF(F9=0,0,G9/F9) -> 0.5 | M9: 4 місце
A10: Група 1 | B10: 5 | C10: Г1-Т5 Бичков / Пархоменко | D10: Бичков / Пархоменко | E10: Пул B | F10: =COUNTIF(Fact_Matches!$F$2:$F$49,C10)+COUNTIF(Fact_Matches!$I$2:$I$49,C10) -> 5 | G10: =COUNTIF(Fact_Matches!$J$2:$J$49,C10) -> 3 | H10: =F10-G10 -> 2 | I10: =SUMIF(Fact_Matches!$F$2:$F$49,C10,Fact_Matches!$G$2:$G$49)+SUMIF(Fact_Matches!$I$2:$I$49,C10,Fact_Matches!$H$2:$H$49) -> 44 | J10: =SUMIF(Fact_Matches!$F$2:$F$49,C10,Fact_Matches!$H$2:$H$49)+SUMIF(Fact_Matches!$I$2:$I$49,C10,Fact_Matches!$G$2:$G$49) -> 38 | K10: =I10-J10 -> 6 | L10: =IF(F10=0,0,G10/F10) -> 0.6 | M10: 2 місце
A11: Група 1 | B11: 8 | C11: Г1-Т8 Зімін / Папуров | D11: Зімін / Папуров | E11: Пул B | F11: =COUNTIF(Fact_Matches!$F$2:$F$49,C11)+COUNTIF(Fact_Matches!$I$2:$I$49,C11) -> 3 | G11: =COUNTIF(Fact_Matches!$J$2:$J$49,C11) -> 2 | H11: =F11-G11 -> 1 | I11: =SUMIF(Fact_Matches!$F$2:$F$49,C11,Fact_Matches!$G$2:$G$49)+SUMIF(Fact_Matches!$I$2:$I$49,C11,Fact_Matches!$H$2:$H$49) -> 27 | J11: =SUMIF(Fact_Matches!$F$2:$F$49,C11,Fact_Matches!$H$2:$H$49)+SUMIF(Fact_Matches!$I$2:$I$49,C11,Fact_Matches!$G$2:$G$49) -> 21 | K11: =I11-J11 -> 6 | L11: =IF(F11=0,0,G11/F11) -> 0.66666667 | M11: Вибули в групі
A12: Група 1 | B12: 4 | C12: Г1-Т4 Барбінягра / Лапшинський | D12: Барбінягра / Лапшинський | E12: Пул A | F12: =COUNTIF(Fact_Matches!$F$2:$F$49,C12)+COUNTIF(Fact_Matches!$I$2:$I$49,C12) -> 3 | G12: =COUNTIF(Fact_Matches!$J$2:$J$49,C12) -> 1 | H12: =F12-G12 -> 2 | I12: =SUMIF(Fact_Matches!$F$2:$F$49,C12,Fact_Matches!$G$2:$G$49)+SUMIF(Fact_Matches!$I$2:$I$49,C12,Fact_Matches!$H$2:$H$49) -> 23 | J12: =SUMIF(Fact_Matches!$F$2:$F$49,C12,Fact_Matches!$H$2:$H$49)+SUMIF(Fact_Matches!$I$2:$I$49,C12,Fact_Matches!$G$2:$G$49) -> 24 | K12: =I12-J12 -> -1 | L12: =IF(F12=0,0,G12/F12) -> 0.33333333 | M12: Вибули в групі
A13: Група 2 | B13: 5 | C13: Г2-Т5 Прокопович / Кравцов | D13: Прокопович / Кравцов | E13: Пул C | F13: =COUNTIF(Fact_Matches!$F$2:$F$49,C13)+COUNTIF(Fact_Matches!$I$2:$I$49,C13) -> 3 | G13: =COUNTIF(Fact_Matches!$J$2:$J$49,C13) -> 1 | H13: =F13-G13 -> 2 | I13: =SUMIF(Fact_Matches!$F$2:$F$49,C13,Fact_Matches!$G$2:$G$49)+SUMIF(Fact_Matches!$I$2:$I$49,C13,Fact_Matches!$H$2:$H$49) -> 18 | J13: =SUMIF(Fact_Matches!$F$2:$F$49,C13,Fact_Matches!$H$2:$H$49)+SUMIF(Fact_Matches!$I$2:$I$49,C13,Fact_Matches!$G$2:$G$49) -> 24 | K13: =I13-J13 -> -6 | L13: =IF(F13=0,0,G13/F13) -> 0.33333333 | M13: 1/4 фіналу
... A23: Група 2 | B23: 11 | C23: Г2-Т11 Пазиніч / Олейник | D23: Пазиніч / Олейник | E23: Пул A | F23: =COUNTIF(Fact_Matches!$F$2:$F$49,C23)+COUNTIF(Fact_Matches!$I$2:$I$49,C23) -> 3 | G23: =COUNTIF(Fact_Matches!$J$2:$J$49,C23) -> 0 | H23: =F23-G23 -> 3 | I23: =SUMIF(Fact_Matches!$F$2:$F$49,C23,Fact_Matches!$G$2:$G$49)+SUMIF(Fact_Matches!$I$2:$I$49,C23,Fact_Matches!$H$2:$H$49) -> 0 | J23: =SUMIF(Fact_Matches!$F$2:$F$49,C23,Fact_Matches!$H$2:$H$49)+SUMIF(Fact_Matches!$I$2:$I$49,C23,Fact_Matches!$G$2:$G$49) -> 33 | K23: =I23-J23 -> -33 | L23: =IF(F23=0,0,G23/F23) -> 0 | M23: Вибули в групі

Sheet Fact_Matches
A1: MatchID | B1: Tournament | C1: Stage | D1: Round | E1: Pool | F1: Team1 | G1: Score1 | H1: Score2 | I1: Team2 | J1: Winner | K1: Margin | L1: Total
A2: Г1-М1 | B2: Група 1 | C2: Груповий етап | D2: Тур 1 | E2: Пул A | F2: Г1-Т1 Рябошапко / Олейник | G2: 11 | H2: 2 | I2: Г1-Т3 Кутовой / Куліков | J2: =IF(G2>H2,F2,I2) -> Г1-Т1 Рябошапко / Олейник | K2: =ABS(G2-H2) -> 9 | L2: =G2+H2 -> 13
A3: Г1-М2 | B3: Група 1 | C3: Груповий етап | D3: Тур 1 | E3: Пул A | F3: Г1-Т4 Барбінягра / Лапшинський | G3: 11 | H3: 2 | I3: Г1-Т7 Лещенко / Москалюк | J3: =IF(G3>H3,F3,I3) -> Г1-Т4 Барбінягра / Лапшинський | K3: =ABS(G3-H3) -> 9 | L3: =G3+H3 -> 13
A4: Г1-М3 | B4: Група 1 | C4: Груповий етап | D4: Тур 2 | E4: Пул A | F4: Г1-Т1 Рябошапко / Олейник | G4: 11 | H4: 3 | I4: Г1-Т4 Барбінягра / Лапшинський | J4: =IF(G4>H4,F4,I4) -> Г1-Т1 Рябошапко / Олейник | K4: =ABS(G4-H4) -> 8 | L4: =G4+H4 -> 14
A5: Г1-М4 | B5: Група 1 | C5: Груповий етап | D5: Тур 2 | E5: Пул A | F5: Г1-Т3 Кутовой / Куліков | G5: 11 | H5: 2 | I5: Г1-Т7 Лещенко / Москалюк | J5: =IF(G5>H5,F5,I5) -> Г1-Т3 Кутовой / Куліков | K5: =ABS(G5-H5) -> 9 | L5: =G5+H5 -> 13
A6: Г1-М5 | B6: Група 1 | C6: Груповий етап | D6: Тур 3 | E6: Пул A | F6: Г1-Т1 Рябошапко / Олейник | G6: 11 | H6: 2 | I6: Г1-Т7 Лещенко / Москалюк | J6: =IF(G6>H6,F6,I6) -> Г1-Т1 Рябошапко / Олейник | K6: =ABS(G6-H6) -> 9 | L6: =G6+H6 -> 13
A7: Г1-М6 | B7: Група 1 | C7: Груповий етап | D7: Тур 3 | E7: Пул A | F7: Г1-Т3 Кутовой / Куліков | G7: 11 | H7: 9 | I7: Г1-Т4 Барбінягра / Лапшинський | J7: =IF(G7>H7,F7,I7) -> Г1-Т3 Кутовой / Куліков | K7: =ABS(G7-H7) -> 2 | L7: =G7+H7 -> 20
A8: Г1-М7 | B8: Група 1 | C8: Груповий етап | D8: Тур 1 | E8: Пул B | F8: Г1-Т2 Кухаренко / Васильєв | G8: 3 | H8: 11 | I8: Г1-Т5 Бичков / Пархоменко | J8: =IF(G8>H8,F8,I8) -> Г1-Т5 Бичков / Пархоменко | K8: =ABS(G8-H8) -> 8 | L8: =G8+H8 -> 14
A9: Г1-М8 | B9: Група 1 | C9: Груповий етап | D9: Тур 1 | E9: Пул B | F9: Г1-Т6 Довгань / Катеринич О. | G9: 8 | H9: 11 | I9: Г1-Т8 Зімін / Папуров | J9: =IF(G9>H9,F9,I9) -> Г1-Т8 Зімін / Папуров | K9: =ABS(G9-H9) -> 3 | L9: =G9+H9 -> 19
A10: Г1-М9 | B10: Група 1 | C10: Груповий етап | D10: Тур 2 | E10: Пул B | F10: Г1-Т2 Кухаренко / Васильєв | G10: 4 | H10: 11 | I10: Г1-Т6 Довгань / Катеринич О. | J10: =IF(G10>H10,F10,I10) -> Г1-Т6 Довгань / Катеринич О. | K10: =ABS(G10-H10) -> 7 | L10: =G10+H10 -> 15
A11: Г1-М10 | B11: Група 1 | C11: Груповий етап | D11: Тур 2 | E11: Пул B | F11: Г1-Т5 Бичков / Пархоменко | G11: 11 | H11: 5 | I11: Г1-Т8 Зімін / Папуров | J11: =IF(G11>H11,F11,I11) -> Г1-Т5 Бичков / Пархоменко | K11: =ABS(G11-H11) -> 6 | L11: =G11+H11 -> 16
A12: Г1-М11 | B12: Група 1 | C12: Груповий етап | D12: Тур 3 | E12: Пул B | F12: Г1-Т2 Кухаренко / Васильєв | G12: 2 | H12: 11 | I12: Г1-Т8 Зімін / Папуров | J12: =IF(G12>H12,F12,I12) -> Г1-Т8 Зімін / Папуров | K12: =ABS(G12-H12) -> 9 | L12: =G12+H12 -> 13
A13: Г1-М12 | B13: Група 1 | C13: Груповий етап | D13: Тур 3 | E13: Пул B | F13: Г1-Т5 Бичков / Пархоменко | G13: 4 | H13: 11 | I13: Г1-Т6 Довгань / Катеринич О. | J13: =IF(G13>H13,F13,I13) -> Г1-Т6 Довгань / Катеринич О. | K13: =ABS(G13-H13) -> 7 | L13: =G13+H13 -> 15
A14: Г1-ПФ1 | B14: Група 1 | C14: Play-off | D14: 1/2 фіналу | F14: Г1-Т1 Рябошапко / Олейник | G14: 8 | H14: 11 | I14: Г1-Т5 Бичков / Пархоменко | J14: =IF(G14>H14,F14,I14) -> Г1-Т5 Бичков / Пархоменко | K14: =ABS(G14-H14) -> 3 | L14: =G14+H14 -> 19
A15: Г1-ПФ2 | B15: Група 1 | C15: Play-off | D15: 1/2 фіналу | F15: Г1-Т6 Довгань / Катеринич О. | G15: 11 | H15: 2 | I15: Г1-Т3 Кутовой / Куліков | J15: =IF(G15>H15,F15,I15) -> Г1-Т6 Довгань / Катеринич О. | K15: =ABS(G15-H15) -> 9 | L15: =G15+H15 -> 13
A16: Г1-Бронза | B16: Група 1 | C16: Play-off | D16: За 3 місце | F16: Г1-Т1 Рябошапко / Олейник | G16: 11 | H16: 2 | I16: Г1-Т3 Кутовой / Куліков | J16: =IF(G16>H16,F16,I16) -> Г1-Т1 Рябошапко / Олейник | K16: =ABS(G16-H16) -> 9 | L16: =G16+H16 -> 13
A17: Г1-Фінал | B17: Група 1 | C17: Play-off | D17: Фінал | F17: Г1-Т5 Бичков / Пархоменко | G17: 7 | H17: 11 | I17: Г1-Т6 Довгань / Катеринич О. | J17: =IF(G17>H17,F17,I17) -> Г1-Т6 Довгань / Катеринич О. | K17: =ABS(G17-H17) -> 4 | L17: =G17+H17 -> 18
A18: Г2-М1 | B18: Група 2 | C18: Груповий етап | D18: Тур 1 | E18: Пул A | F18: Г2-Т3 Концевой / Парфенюк | G18: 11 | H18: 0 | I18: Г2-Т11 Пазиніч / Олейник | J18: =IF(G18>H18,F18,I18) -> Г2-Т3 Концевой / Парфенюк | K18: =ABS(G18-H18) -> 11 | L18: =G18+H18 -> 11
A19: Г2-М2 | B19: Група 2 | C19: Груповий етап | D19: Тур 1 | E19: Пул A | F19: Г2-Т12 Делігіоз / Цап | G19: 0 | H19: 11 | I19: Г2-Т13 Фещук / Гиряк | J19: =IF(G19>H19,F19,I19) -> Г2-Т13 Фещук / Гиряк | K19: =ABS(G19-H19) -> 11 | L19: =G19+H19 -> 11
A20: Г2-М3 | B20: Група 2 | C20: Груповий етап | D20: Тур 2 | E20: Пул A | F20: Г2-Т3 Концевой / Парфенюк | G20: 11 | H20: 3 | I20: Г2-Т12 Делігіоз / Цап | J20: =IF(G20>H20,F20,I20) -> Г2-Т3 Концевой / Парфенюк | K20: =ABS(G20-H20) -> 8 | L20: =G20+H20 -> 14
A21: Г2-М4 | B21: Група 2 | C21: Груповий етап | D21: Тур 2 | E21: Пул A | F21: Г2-Т11 Пазиніч / Олейник | G21: 0 | H21: 11 | I21: Г2-Т13 Фещук / Гиряк | J21: =IF(G21>H21,F21,I21) -> Г2-Т13 Фещук / Гиряк | K21: =ABS(G21-H21) -> 11 | L21: =G21+H21 -> 11
A22: Г2-М5 | B22: Група 2 | C22: Груповий етап | D22: Тур 3 | E22: Пул A | F22: Г2-Т3 Концевой / Парфенюк | G22: 11 | H22: 7 | I22: Г2-Т13 Фещук / Гиряк | J22: =IF(G22>H22,F22,I22) -> Г2-Т3 Концевой / Парфенюк | K22: =ABS(G22-H22) -> 4 | L22: =G22+H22 -> 18
A23: Г2-М6 | B23: Група 2 | C23: Груповий етап | D23: Тур 3 | E23: Пул A | F23: Г2-Т11 Пазиніч / Олейник | G23: 0 | H23: 11 | I23: Г2-Т12 Делігіоз / Цап | J23: =IF(G23>H23,F23,I23) -> Г2-Т12 Делігіоз / Цап | K23: =ABS(G23-H23) -> 11 | L23: =G23+H23 -> 11
A24: Г2-М7 | B24: Група 2 | C24: Груповий етап | D24: Тур 1 | E24: Пул B | F24: Г2-Т4 Тарарака / Татаров | G24: 11 | H24: 13 | I24: Г2-Т7 Орєшин / Грибонос | J24: =IF(G24>H24,F24,I24) -> Г2-Т7 Орєшин / Грибонос | K24: =ABS(G24-H24) -> 2 | L24: =G24+H24 -> 24
A25: Г2-М8 | B25: Група 2 | C25: Груповий етап | D25: Тур 1 | E25: Пул B | F25: Г2-Т9 Горковець / Толкачов | G25: 0 | H25: 11 | I25: Г2-Т14 Трач / Дучєв | J25: =IF(G25>H25,F25,I25) -> Г2-Т14 Трач / Дучєв | K25: =ABS(G25-H25) -> 11 | L25: =G25+H25 -> 11
A26: Г2-М9 | B26: Група 2 | C26: Груповий етап | D26: Тур 2 | E26: Пул B | F26: Г2-Т4 Тарарака / Татаров | G26: 11 | H26: 0 | I26: Г2-Т9 Горковець / Толкачов | J26: =IF(G26>H26,F26,I26) -> Г2-Т4 Тарарака / Татаров | K26: =ABS(G26-H26) -> 11 | L26: =G26+H26 -> 11
A27: Г2-М10 | B27: Група 2 | C27: Груповий етап | D27: Тур 2 | E27: Пул B | F27: Г2-Т7 Орєшин / Грибонос | G27: 11 | H27: 4 | I27: Г2-Т14 Трач / Дучєв | J27: =IF(G27>H27,F27,I27) -> Г2-Т7 Орєшин / Грибонос | K27: =ABS(G27-H27) -> 7 | L27: =G27+H27 -> 15
A28: Г2-М11 | B28: Група 2 | C28: Груповий етап | D28: Тур 3 | E28: Пул B | F28: Г2-Т4 Тарарака / Татаров | G28: 11 | H28: 0 | I28: Г2-Т14 Трач / Дучєв | J28: =IF(G28>H28,F28,I28) -> Г2-Т4 Тарарака / Татаров | K28: =ABS(G28-H28) -> 11 | L28: =G28+H28 -> 11
A29: Г2-М12 | B29: Група 2 | C29: Груповий етап | D29: Тур 3 | E29: Пул B | F29: Г2-Т7 Орєшин / Грибонос | G29: 11 | H29: 0 | I29: Г2-Т9 Горковець / Толкачов | J29: =IF(G29>H29,F29,I29) -> Г2-Т7 Орєшин / Грибонос | K29: =ABS(G29-H29) -> 11 | L29: =G29+H29 -> 11
... A35: Г2-М18 | B35: Група 2 | C35: Груповий етап | D35: Тур 3 | E35: Пул D | F35: Г2-Т6 Глухов / Змієвський | G35: 11 | H35: 2 | I35: Г2-Т8 Камінський / Дідик | J35: =IF(G35>H35,F35,I35) -> Г2-Т6 Глухов / Змієвський | K35: =ABS(G35-H35) -> 9 | L35: =G35+H35 -> 13
A36: Г2-ЧФ1 | B36: Група 2 | C36: Play-off | D36: 1/4 фіналу | F36: Г2-Т3 Концевой / Парфенюк | G36: 8 | H36: 11 | I36: Г2-Т4 Тарарака / Татаров | J36: =IF(G36>H36,F36,I36) -> Г2-Т4 Тарарака / Татаров | K36: =ABS(G36-H36) -> 3 | L36: =G36+H36 -> 19
A37: Г2-ЧФ2 | B37: Група 2 | C37: Play-off | D37: 1/4 фіналу | F37: Г2-Т2 Салабай / Шульга | G37: 11 | H37: 2 | I37: Г2-Т6 Глухов / Змієвський | J37: =IF(G37>H37,F37,I37) -> Г2-Т2 Салабай / Шульга | K37: =ABS(G37-H37) -> 9 | L37: =G37+H37 -> 13
A38: Г2-ЧФ3 | B38: Група 2 | C38: Play-off | D38: 1/4 фіналу | F38: Г2-Т7 Орєшин / Грибонос | G38: 8 | H38: 11 | I38: Г2-Т13 Фещук / Гиряк | J38: =IF(G38>H38,F38,I38) -> Г2-Т13 Фещук / Гиряк | K38: =ABS(G38-H38) -> 3 | L38: =G38+H38 -> 19
A39: Г2-ЧФ4 | B39: Група 2 | C39: Play-off | D39: 1/4 фіналу | F39: Г2-Т1 Сторожук / Нестерчук | G39: 11 | H39: 2 | I39: Г2-Т5 Прокопович / Кравцов | J39: =IF(G39>H39,F39,I39) -> Г2-Т1 Сторожук / Нестерчук | K39: =ABS(G39-H39) -> 9 | L39: =G39+H39 -> 13
A40: Г2-ПФ1 | B40: Група 2 | C40: Play-off | D40: 1/2 фіналу | F40: Г2-Т4 Тарарака / Татаров | G40: 7 | H40: 11 | I40: Г2-Т2 Салабай / Шульга | J40: =IF(G40>H40,F40,I40) -> Г2-Т2 Салабай / Шульга | K40: =ABS(G40-H40) -> 4 | L40: =G40+H40 -> 18
A41: Г2-ПФ2 | B41: Група 2 | C41: Play-off | D41: 1/2 фіналу | F41: Г2-Т13 Фещук / Гиряк | G41: 5 | H41: 11 | I41: Г2-Т1 Сторожук / Нестерчук | J41: =IF(G41>H41,F41,I41) -> Г2-Т1 Сторожук / Нестерчук | K41: =ABS(G41-H41) -> 6 | L41: =G41+H41 -> 16
A42: Г2-Бронза | B42: Група 2 | C42: Play-off | D42: За 3 місце | F42: Г2-Т4 Тарарака / Татаров | G42: 11 | H42: 5 | I42: Г2-Т13 Фещук / Гиряк | J42: =IF(G42>H42,F42,I42) -> Г2-Т4 Тарарака / Татаров | K42: =ABS(G42-H42) -> 6 | L42: =G42+H42 -> 16
A43: Г2-Фінал | B43: Група 2 | C43: Play-off | D43: Фінал | F43: Г2-Т2 Салабай / Шульга | G43: 11 | H43: 8 | I43: Г2-Т1 Сторожук / Нестерчук | J43: =IF(G43>H43,F43,I43) -> Г2-Т2 Салабай / Шульга | K43: =ABS(G43-H43) -> 3 | L43: =G43+H43 -> 19
A44: Г3-М1 | B44: Група 3 | C44: Груповий етап | D44: Матч 1 | F44: Котліна В. / Ільїна Н. | G44: 0 | H44: 11 | I44: Папурова А. / Крівонос Г. | J44: =IF(G44>H44,F44,I44) -> Папурова А. / Крівонос Г. | K44: =ABS(G44-H44) -> 11 | L44: =G44+H44 -> 11
A45: Г3-М2 | B45: Група 3 | C45: Груповий етап | D45: Матч 2 | F45: Концева Е. / Папурова А. | G45: 6 | H45: 11 | I45: Крівонос Г. / Катеринич І. | J45: =IF(G45>H45,F45,I45) -> Крівонос Г. / Катеринич І. | K45: =ABS(G45-H45) -> 5 | L45: =G45+H45 -> 17
...

Sheet Dim_Players
A1: RegID | B1: RegTime | C1: Tournament | D1: Pool | E1: TeamNo | F1: Team | G1: Player | H1: Category | I1: Source | J1: RegDate | K1: RegHour
A2: 2 | B2: 46286.385 | C2: Група 1 | D2: Пул A | E2: 1 | F2: Г1-Т1 Рябошапко / Олейник | G2: Рябошапко Арсен | H2: Ветерани на кріслах колісних | I2: Форма реєстрації | J2: =IF(B2="","",INT(B2)) -> 46286 | K2: =IF(B2="","",HOUR(B2)) -> 9
A3: 42 | B3: 46299.409 | C3: Група 1 | D3: Пул A | E3: 1 | F3: Г1-Т1 Рябошапко / Олейник | G3: Олейник Юрій Валерійович | H3: Ветерани на протезах | I3: Форма реєстрації | J3: =IF(B3="","",INT(B3)) -> 46299 | K3: =IF(B3="","",HOUR(B3)) -> 9
C4: Група 1 | D4: Пул A | E4: 3 | F4: Г1-Т3 Кутовой / Куліков | G4: Кутовой Антон | H4: Не вказано | I4: Додано вручну | J4: =IF(B4="","",INT(B4)) | K4: =IF(B4="","",HOUR(B4))
A5: 43 | B5: 46299.468 | C5: Група 1 | D5: Пул A | E5: 3 | F5: Г1-Т3 Кутовой / Куліков | G5: Куліков Євген Олександрович | H5: Ветерани на протезах | I5: Форма реєстрації | J5: =IF(B5="","",INT(B5)) -> 46299 | K5: =IF(B5="","",HOUR(B5)) -> 11
A6: 46 | B6: 46299.821 | C6: Група 1 | D6: Пул A | E6: 4 | F6: Г1-Т4 Барбінягра / Лапшинський | G6: Барбінягра Олександр Іванович | H6: Ветерани на кріслах колісних | I6: Форма реєстрації | J6: =IF(B6="","",INT(B6)) -> 46299 | K6: =IF(B6="","",HOUR(B6)) -> 19
A7: 27 | B7: 46291.561 | C7: Група 1 | D7: Пул A | E7: 4 | F7: Г1-Т4 Барбінягра / Лапшинський | G7: Лапшинський Олександр Анатолійович | H7: Ветерани з невидимими травмами | I7: Форма реєстрації | J7: =IF(B7="","",INT(B7)) -> 46291 | K7: =IF(B7="","",HOUR(B7)) -> 13
A8: 26 | B8: 46291.371 | C8: Група 1 | D8: Пул A | E8: 7 | F8: Г1-Т7 Лещенко / Москалюк | G8: Лещенко Валентин Валерійович | H8: Ветерани на кріслах колісних | I8: Форма реєстрації | J8: =IF(B8="","",INT(B8)) -> 46291 | K8: =IF(B8="","",HOUR(B8)) -> 8
A9: 40 | B9: 46298.914 | C9: Група 1 | D9: Пул A | E9: 7 | F9: Г1-Т7 Лещенко / Москалюк | G9: Москалюк Вадим Васильович | H9: Ветерани з невидимими травмами | I9: Форма реєстрації | J9: =IF(B9="","",INT(B9)) -> 46298 | K9: =IF(B9="","",HOUR(B9)) -> 21
C10: Група 1 | D10: Пул B | E10: 2 | F10: Г1-Т2 Кухаренко / Васильєв | G10: Кухаренко Олександр | H10: Не вказано | I10: Додано вручну | J10: =IF(B10="","",INT(B10)) | K10: =IF(B10="","",HOUR(B10))
A11: 17 | B11: 46288.916 | C11: Група 1 | D11: Пул B | E11: 2 | F11: Г1-Т2 Кухаренко / Васильєв | G11: Васильєв Олексій Михайлович | H11: Ветерани з невидимими травмами | I11: Форма реєстрації | J11: =IF(B11="","",INT(B11)) -> 46288 | K11: =IF(B11="","",HOUR(B11)) -> 21
A12: 28 | B12: 46291.565 | C12: Група 1 | D12: Пул B | E12: 5 | F12: Г1-Т5 Бичков / Пархоменко | G12: Бичков Олег Володимирович | H12: Ветерани на кріслах колісних | I12: Форма реєстрації | J12: =IF(B12="","",INT(B12)) -> 46291 | K12: =IF(B12="","",HOUR(B12)) -> 13
A13: 18 | B13: 46288.99 | C13: Група 1 | D13: Пул B | E13: 5 | F13: Г1-Т5 Бичков / Пархоменко | G13: Пархоменко Максим Миколайович | H13: Ветерани на протезах | I13: Форма реєстрації | J13: =IF(B13="","",INT(B13)) -> 46288 | K13: =IF(B13="","",HOUR(B13)) -> 23
C14: Група 1 | D14: Пул B | E14: 6 | F14: Г1-Т6 Довгань / Катеринич О. | G14: Довгань Олександр | H14: Не вказано | I14: Додано вручну | J14: =IF(B14="","",INT(B14)) | K14: =IF(B14="","",HOUR(B14))
A15: 7 | B15: 46286.672 | C15: Група 1 | D15: Пул B | E15: 6 | F15: Г1-Т6 Довгань / Катеринич О. | G15: Катеринич Олександр Олександрович | H15: Ветерани на протезах | I15: Форма реєстрації | J15: =IF(B15="","",INT(B15)) -> 46286 | K15: =IF(B15="","",HOUR(B15)) -> 16
A16: 3 | B16: 46286.387 | C16: Група 1 | D16: Пул B | E16: 8 | F16: Г1-Т8 Зімін / Папуров | G16: Зімін Михайло Володимирович | H16: Ветерани на кріслах колісних | I16: Форма реєстрації | J16: =IF(B16="","",INT(B16)) -> 46286 | K16: =IF(B16="","",HOUR(B16)) -> 9
A17: 4 | B17: 46286.417 | C17: Група 1 | D17: Пул B | E17: 8 | F17: Г1-Т8 Зімін / Папуров | G17: Папуров Григорій Георгійович | H17: Ветерани з невидимими травмами | I17: Форма реєстрації | J17: =IF(B17="","",INT(B17)) -> 46286 | K17: =IF(B17="","",HOUR(B17)) -> 10
A18: 11 | B18: 46287.766 | C18: Група 2 | D18: Пул A | E18: 3 | F18: Г2-Т3 Концевой / Парфенюк | G18: Концевой Сергій Миколайович | H18: Ветерани з невидимими травмами | I18: Форма реєстрації | J18: =IF(B18="","",INT(B18)) -> 46287 | K18: =IF(B18="","",HOUR(B18)) -> 18
A19: 6 | B19: 46286.452 | C19: Група 2 | D19: Пул A | E19: 3 | F19: Г2-Т3 Концевой / Парфенюк | G19: Парфенюк Сергій Олександрович | H19: Ветерани з невидимими травмами | I19: Форма реєстрації | J19: =IF(B19="","",INT(B19)) -> 46286 | K19: =IF(B19="","",HOUR(B19)) -> 10
C20: Група 2 | D20: Пул A | E20: 11 | F20: Г2-Т11 Пазиніч / Олейник | G20: Пазиніч Сергій Анатолійович | H20: Не вказано | I20: Додано вручну | J20: =IF(B20="","",INT(B20)) | K20: =IF(B20="","",HOUR(B20))
A21: 15 | B21: 46288.601 | C21: Група 2 | D21: Пул A | E21: 11 | F21: Г2-Т11 Пазиніч / Олейник | G21: Олейник Юрій Валерійович | H21: Ветерани з невидимими травмами | I21: Форма реєстрації | J21: =IF(B21="","",INT(B21)) -> 46288 | K21: =IF(B21="","",HOUR(B21)) -> 14
A22: 29 | B22: 46291.78 | C22: Група 2 | D22: Пул A | E22: 12 | F22: Г2-Т12 Делігіоз / Цап | G22: Делігіоз Андрій Георгійович | H22: Ветерани з невидимими травмами | I22: Форма реєстрації | J22: =IF(B22="","",INT(B22)) -> 46291 | K22: =IF(B22="","",HOUR(B22)) -> 18
C23: Група 2 | D23: Пул A | E23: 12 | F23: Г2-Т12 Делігіоз / Цап | G23: Цап Олег | H23: Не вказано | I23: Додано вручну | J23: =IF(B23="","",INT(B23)) | K23: =IF(B23="","",HOUR(B23))
C24: Група 2 | D24: Пул A | E24: 13 | F24: Г2-Т13 Фещук / Гиряк | G24: Фещук Данило Олександрович | H24: Не вказано | I24: Додано вручну | J24: =IF(B24="","",INT(B24)) | K24: =IF(B24="","",HOUR(B24))
C25: Група 2 | D25: Пул A | E25: 13 | F25: Г2-Т13 Фещук / Гиряк | G25: Гиряк Роман Михайлович | H25: Не вказано | I25: Додано вручну | J25: =IF(B25="","",INT(B25)) | K25: =IF(B25="","",HOUR(B25))
A26: 49 | B26: 46299.85 | C26: Група 2 | D26: Пул B | E26: 4 | F26: Г2-Т4 Тарарака / Татаров | G26: Тарарака Олексій Борисович | H26: Ветерани з невидимими травмами | I26: Форма реєстрації | J26: =IF(B26="","",INT(B26)) -> 46299 | K26: =IF(B26="","",HOUR(B26)) -> 20
A27: 13 | B27: 46288.527 | C27: Група 2 | D27: Пул B | E27: 4 | F27: Г2-Т4 Тарарака / Татаров | G27: Татаров Руслан Сергійович | H27: Ветерани з невидимими травмами | I27: Форма реєстрації | J27: =IF(B27="","",INT(B27)) -> 46288 | K27: =IF(B27="","",HOUR(B27)) -> 12
A28: 19 | B28: 46289.396 | C28: Група 2 | D28: Пул B | E28: 7 | F28: Г2-Т7 Орєшин / Грибонос | G28: Орєшин Микола Семенович | H28: Ветерани з невидимими травмами | I28: Форма реєстрації | J28: =IF(B28="","",INT(B28)) -> 46289 | K28: =IF(B28="","",HOUR(B28)) -> 9
A29: 22 | B29: 46289.523 | C29: Група 2 | D29: Пул B | E29: 7 | F29: Г2-Т7 Орєшин / Грибонос | G29: Грибонос Олександр Володиморович | H29: Ветерани з невидимими травмами | I29: Форма реєстрації | J29: =IF(B29="","",INT(B29)) -> 46289 | K29: =IF(B29="","",HOUR(B29)) -> 12
A30: 36 | B30: 46296.491 | C30: Група 2 | D30: Пул B | E30: 9 | F30: Г2-Т9 Горковець / Толкачов | G30: Горковець Андрій Георгійович | H30: Ветерани з невидимими травмами | I30: Форма реєстрації | J30: =IF(B30="","",INT(B30)) -> 46296 | K30: =IF(B30="","",HOUR(B30)) -> 11
A31: 37 | B31: 46296.497 | C31: Група 2 | D31: Пул B | E31: 9 | F31: Г2-Т9 Горковець / Толкачов | G31: Толкачов Сергій Вікторович | H31: Ветерани з невидимими травмами | I31: Форма реєстрації | J31: =IF(B31="","",INT(B31)) -> 46296 | K31: =IF(B31="","",HOUR(B31)) -> 11
C32: Група 2 | D32: Пул B | E32: 14 | F32: Г2-Т14 Трач / Дучєв | G32: Трач Ігор Іванович | H32: Не вказано | I32: Додано вручну | J32: =IF(B32="","",INT(B32)) | K32: =IF(B32="","",HOUR(B32))
A33: 5 | B33: 46286.424 | C33: Група 2 | D33: Пул B | E33: 14 | F33: Г2-Т14 Трач / Дучєв | G33: Дучєв Максим Палович | H33: Ветерани з невидимими травмами | I33: Форма реєстрації | J33: =IF(B33="","",INT(B33)) -> 46286 | K33: =IF(B33="","",HOUR(B33)) -> 10
A34: 30 | B34: 46292.654 | C34: Група 2 | D34: Пул C | E34: 2 | F34: Г2-Т2 Салабай / Шульга | G34: Салабай Олександр | H34: Ветерани без поранень | I34: Форма реєстрації | J34: =IF(B34="","",INT(B34)) -> 46292 | K34: =IF(B34="","",HOUR(B34)) -> 15
C35: Група 2 | D35: Пул C | E35: 2 | F35: Г2-Т2 Салабай / Шульга | G35: Шульга Андрей | H35: Ветерани без поранень | I35: Додано вручну | J35: =IF(B35="","",INT(B35)) | K35: =IF(B35="","",HOUR(B35))
A36: 38 | B36: 46296.62 | C36: Група 2 | D36: Пул C | E36: 5 | F36: Г2-Т5 Прокопович / Кравцов | G36: Прокопович Сергій Михайлович | H36: Ветерани з невидимими травмами | I36: Форма реєстрації | J36: =IF(B36="","",INT(B36)) -> 46296 | K36: =IF(B36="","",HOUR(B36)) -> 14
A37: 1 | B37: 46286.383 | C37: Група 2 | D37: Пул C | E37: 5 | F37: Г2-Т5 Прокопович / Кравцов | G37: Кравцов Олександр Сергійович | H37: Ветерани з невидимими травмами | I37: Форма реєстрації | J37: =IF(B37="","",INT(B37)) -> 46286 | K37: =IF(B37="","",HOUR(B37)) -> 9
A38: 45 | B38: 46299.767 | C38: Група 2 | D38: Пул C | E38: 10 | F38: Г2-Т10 Кривонос / Мазур | G38: Кривонос Андрій Миколайович | H38: Ветерани з невидимими травмами | I38: Форма реєстрації | J38: =IF(B38="","",INT(B38)) -> 46299 | K38: =IF(B38="","",HOUR(B38)) -> 18
C39: Група 2 | D39: Пул C | E39: 10 | F39: Г2-Т10 Кривонос / Мазур | G39: Мазур Володімір | H39: Не вказано | I39: Додано вручну | J39: =IF(B39="","",INT(B39)) | K39: =IF(B39="","",HOUR(B39))
A40: 14 | B40: 46288.545 | C40: Група 2 | D40: Пул D | E40: 1 | F40: Г2-Т1 Сторожук / Нестерчук | G40: Сторожук Микола Миколайович | H40: Ветерани з невидимими травмами | I40: Форма реєстрації | J40: =IF(B40="","",INT(B40)) -> 46288 | K40: =IF(B40="","",HOUR(B40)) -> 13
...

Sheet PQ_DAX
A1: Міні-проєкт Power Query + Power Pivot (DAX)
A3: Крок 0. Підготовка
A4: Таблиці вже оформлені як Excel Tables: Dim_Players, Fact_Matches, Dim_Teams.
A5: Справжні PivotTable створюються в Excel (Insert - PivotTable - Use this workbook's Data Model). Аркуші Pivot_* містять той самий результат у вигляді формул.
A7: Крок 1. Power Query: qPlayers (Data - From Table/Range, потім Advanced Editor)
A8: let
A9: Source = Excel.CurrentWorkbook(){[Name="Dim_Players"]}[Content],
A10: Typed = Table.TransformColumnTypes(Source, {{"RegID", Int64.Type}, {"RegTime", type datetime}}),
A11: NoCalc = Table.RemoveColumns(Typed, {"RegDate", "RegHour"}),
A12: Day = Table.AddColumn(NoCalc, "RegDay", each DateTime.Date([RegTime]), type date),
A13: Hour = Table.AddColumn(Day, "Hour", each if [RegTime] = null then null else Time.Hour(DateTime.Time([RegTime])), Int64.Type)
A14: in
... A71: Команди: Dim_Teams[Team] у рядки, мірами Win %, Point Diff; зріз за Tournament.
