Workbook

Sheet Группа 1
C1: Группа | D1: Команда | E1: Игрок
A2: 2 | B2: 46286.385 | C2: 1 | D2: 1 | E2: Рябошапко Арсен | F2: 2 | G2: 2 | H2: ТАК | I2: Ветерани на кріслах колісних колісних | L2: ТАК
A3: 42 | B3: 46299.409 | C3: 1 | D3: 1.2 | E3: Олейник Юрій Валерійович | F3: 2 | G3: 2 | H3: Ширяєв Михайло Юрійович | I3: Ветерани на протезах | L3: ТАК
C4: 1 | D4: 3 | E4: Кутовой Антон | F4: 2 | G4: 2
A5: 43 | B5: 46299.468 | C5: 1 | D5: 3.2 | E5: Куліков Євген Олександрович | F5: 2 | G5: 2 | H5: ТАК | I5: Ветерани на протезах | L5: ТАК
A6: 46 | B6: 46299.821 | C6: 1 | D6: 4 | E6: Барбінягра Олександр Іванович | F6: 2 | G6: 2 | H6: ТАК | I6: Ветерани на кріслах колісних колісних | L6: ТАК
A7: 27 | B7: 46291.561 | C7: 1 | D7: 4.2 | E7: Лапшинський Олександр Анатолійович | F7: 2 | G7: 1 | H7: ТАК | I7: Ветерани з невидимими травмами | L7: ТАК
A8: 26 | B8: 46291.371 | C8: 1 | D8: 7 | E8: Лещенко Валентин Валерійович | F8: 2 | G8: 2 | H8: ТАК | I8: Ветерани на кріслах колісних колісних | L8: ТАК
A9: 40 | B9: 46298.914 | C9: 1 | D9: 7.2 | E9: Москалюк Вадим Васильович | F9: 2 | G9: 1 | H9: ТАК | I9: Ветерани з невидимими травмами | L9: ТАК
C10: 2 | D10: 2 | E10: Кухаренко Олександр | F10: 2 | G10: 2
A11: 17 | B11: 46288.916 | C11: 2 | D11: 2.2 | E11: Васильєв Олексій Михайлович | F11: 2 | G11: 1 | H11: ТАК | I11: Ветерани з невидимими травмами | L11: ТАК
A12: 28 | B12: 46291.565 | C12: 2 | D12: 5 | E12: Бичков Олег Володимирович | F12: 2 | G12: 2 | H12: ТАК | I12: Ветерани на кріслах колісних колісних | L12: ТАК
A13: 18 | B13: 46288.99 | C13: 2 | D13: 5.2 | E13: Пархоменко Максим Миколайович | F13: 2 | G13: 2 | H13: ТАК | I13: Ветерани на протезах | L13: ТАК
C14: 2 | D14: 6 | E14: Довгань Олександр | F14: 2 | G14: 2
A15: 7 | B15: 46286.672 | C15: 2 | D15: 6.2 | E15: Катеринич Олександр Олександрович | F15: 2 | G15: 2 | H15: ТАК | I15: Ветерани на протезах | L15: ТАК
A16: 3 | B16: 46286.387 | C16: 2 | D16: 8 | E16: Зімін Михайло Володимирович | F16: 2 | G16: 2 | H16: ТАК | I16: Ветерани на кріслах колісних колісних | L16: ТАК
A17: 4 | B17: 46286.417 | C17: 2 | D17: 8.2 | E17: Папуров Григорій Георгійович | F17: 2 | G17: 1 | H17: ТАК | I17: Ветерани з невидимими травмами | L17: ТАК
G187: 16
G188: 28
G189: 5
G191: 4
G193: 4 | H193: 14

Sheet Сетка Группа 1
B2: ТУРНІР З ПІКЛБОЛУ — ГРУПА 1 (ВЕТЕРАНИ)
B4: ТАБЛИЦЯ ГРУПИ 1 | M4: ФІНАЛЬНА СІТКА PLAY-OFF (1/2 ФІНАЛУ ТА ФІНАЛИ)
B5: № | C5: Команда (Пара) | D5: Ігри | E5: В | F5: П | G5: Очки (+) | H5: Очки (-) | I5: Різниця (±) | J5: Місце | M5: Стадія | N5: Матч | O5: Команда 1 | P5: Очки 1 | Q5: : | R5: Очки 2 | S5: Команда 2 | T5: Переможець матчу | U5: Статус | V5: Примітка / Наступний етап
B6: 1 | C6: ="Команда 1 (" & 'Группа 1'!E2 & " / " & 'Группа 1'!E3 & ")" -> Команда 1 (Рябошапко Арсен / Олейник Юрій Валерійович) | D6: =COUNTIFS($C$23:$C$28, C6, $I$23:$I$28, "Завершено") + COUNTIFS($G$23:$G$28, C6, $I$23:$I$28, "Завершено") -> 3 | E6: =COUNTIF($H$23:$H$28, C6) -> 3 | F6: =D6 - E6 -> 0 | G6: =SUMIF($C$23:$C$28, C6, $D$23:$D$28) + SUMIF($G$23:$G$28, C6, $F$23:$F$28) -> 33 | H6: =SUMIF($C$23:$C$28, C6, $F$23:$F$28) + SUMIF($G$23:$G$28, C6, $D$23:$D$28) -> 7 | I6: =G6 - H6 -> 26 | J6: =IF(SUM($D$6:$D$9)=0, "—", 1 + COUNTIFS($E$6:$E$9, ">"&E6) + COUNTIFS($E$6:$E$9, E6, $I$6:$I$9, ">"&I6) + COUNTIFS($E$6:$E$9, E6, $I$6:$I$9, I6, $G$6:$G$9, ">"&G6)) -> 1 | M6: 1/2 Фіналу | N6: ПФ 1 | O6: {=IFERROR(INDEX($C$6:$C$9, MATCH(1, $J$6:$J$9, 0)), "1-ше місце Групи 1")} -> Команда 1 (Рябошапко Арсен / Олейник Юрій Валерійович) | P6: 8 | Q6: : | R6: 11 | S6: {=IFERROR(INDEX($C$14:$C$17, MATCH(2, $J$14:$J$17, 0)), "2-ге місце Групи 2")} -> Команда 5 (Бичков Олег Володимирович / Пархоменко Максим Миколайович) | T6: =IF(AND(ISNUMBER(P6),ISNUMBER(R6)),IF(P6>R6,O6,IF(R6>P6,S6,"Нічия")),"—") -> Команда 5 (Бичков Олег Володимирович / Пархоменко Максим Миколайович) | U6: =IF(AND(ISNUMBER(P6),ISNUMBER(R6)),"Завершено","Очікується") -> Завершено | V6: Вихід до Фіналу
B7: 2 | C7: ="Команда 3 (" & 'Группа 1'!E4 & " / " & 'Группа 1'!E5 & ")" -> Команда 3 (Кутовой Антон / Куліков Євген Олександрович) | D7: =COUNTIFS($C$23:$C$28, C7, $I$23:$I$28, "Завершено") + COUNTIFS($G$23:$G$28, C7, $I$23:$I$28, "Завершено") -> 3 | E7: =COUNTIF($H$23:$H$28, C7) -> 2 | F7: =D7 - E7 -> 1 | G7: =SUMIF($C$23:$C$28, C7, $D$23:$D$28) + SUMIF($G$23:$G$28, C7, $F$23:$F$28) -> 24 | H7: =SUMIF($C$23:$C$28, C7, $F$23:$F$28) + SUMIF($G$23:$G$28, C7, $D$23:$D$28) -> 22 | I7: =G7 - H7 -> 2 | J7: =IF(SUM($D$6:$D$9)=0, "—", 1 + COUNTIFS($E$6:$E$9, ">"&E7) + COUNTIFS($E$6:$E$9, E7, $I$6:$I$9, ">"&I7) + COUNTIFS($E$6:$E$9, E7, $I$6:$I$9, I7, $G$6:$G$9, ">"&G7)) -> 2 | M7: 1/2 Фіналу | N7: ПФ 2 | O7: {=IFERROR(INDEX($C$14:$C$17, MATCH(1, $J$14:$J$17, 0)), "1-ше місце Групи 2")} -> Команда 6 (Довгань Олександр / Катеринич Олександр Олександрович) | P7: 11 | Q7: : | R7: 2 | S7: {=IFERROR(INDEX($C$6:$C$9, MATCH(2, $J$6:$J$9, 0)), "2-ге місце Групи 1")} -> Команда 3 (Кутовой Антон / Куліков Євген Олександрович) | T7: =IF(AND(ISNUMBER(P7),ISNUMBER(R7)),IF(P7>R7,O7,IF(R7>P7,S7,"Нічия")),"—") -> Команда 6 (Довгань Олександр / Катеринич Олександр Олександрович) | U7: =IF(AND(ISNUMBER(P7),ISNUMBER(R7)),"Завершено","Очікується") -> Завершено | V7: Вихід до Фіналу
B8: 3 | C8: ="Команда 4 (" & 'Группа 1'!E6 & " / " & 'Группа 1'!E7 & ")" -> Команда 4 (Барбінягра Олександр Іванович / Лапшинський Олександр Анатолійович) | D8: =COUNTIFS($C$23:$C$28, C8, $I$23:$I$28, "Завершено") + COUNTIFS($G$23:$G$28, C8, $I$23:$I$28, "Завершено") -> 3 | E8: =COUNTIF($H$23:$H$28, C8) -> 1 | F8: =D8 - E8 -> 2 | G8: =SUMIF($C$23:$C$28, C8, $D$23:$D$28) + SUMIF($G$23:$G$28, C8, $F$23:$F$28) -> 23 | H8: =SUMIF($C$23:$C$28, C8, $F$23:$F$28) + SUMIF($G$23:$G$28, C8, $D$23:$D$28) -> 24 | I8: =G8 - H8 -> -1 | J8: =IF(SUM($D$6:$D$9)=0, "—", 1 + COUNTIFS($E$6:$E$9, ">"&E8) + COUNTIFS($E$6:$E$9, E8, $I$6:$I$9, ">"&I8) + COUNTIFS($E$6:$E$9, E8, $I$6:$I$9, I8, $G$6:$G$9, ">"&G8)) -> 3
B9: 4 | C9: ="Команда 7 (" & 'Группа 1'!E8 & " / " & 'Группа 1'!E9 & ")" -> Команда 7 (Лещенко Валентин Валерійович / Москалюк Вадим Васильович) | D9: =COUNTIFS($C$23:$C$28, C9, $I$23:$I$28, "Завершено") + COUNTIFS($G$23:$G$28, C9, $I$23:$I$28, "Завершено") -> 3 | E9: =COUNTIF($H$23:$H$28, C9) -> 0 | F9: =D9 - E9 -> 3 | G9: =SUMIF($C$23:$C$28, C9, $D$23:$D$28) + SUMIF($G$23:$G$28, C9, $F$23:$F$28) -> 6 | H9: =SUMIF($C$23:$C$28, C9, $F$23:$F$28) + SUMIF($G$23:$G$28, C9, $D$23:$D$28) -> 33 | I9: =G9 - H9 -> -27 | J9: =IF(SUM($D$6:$D$9)=0, "—", 1 + COUNTIFS($E$6:$E$9, ">"&E9) + COUNTIFS($E$6:$E$9, E9, $I$6:$I$9, ">"&I9) + COUNTIFS($E$6:$E$9, E9, $I$6:$I$9, I9, $G$6:$G$9, ">"&G9)) -> 4 | M9: Матч за 3 місце | N9: Бронза | O9: =IF(AND(ISNUMBER(P6),ISNUMBER(R6)),IF(P6<R6,O6,S6),"Програвший ПФ 1") -> Команда 1 (Рябошапко Арсен / Олейник Юрій Валерійович) | P9: 11 | Q9: : | R9: 2 | S9: =IF(AND(ISNUMBER(P7),ISNUMBER(R7)),IF(P7<R7,O7,S7),"Програвший ПФ 2") -> Команда 3 (Кутовой Антон / Куліков Євген Олександрович) | T9: =IF(AND(ISNUMBER(P9),ISNUMBER(R9)),IF(P9>R9,O9,IF(R9>P9,S9,"Нічия")),"—") -> Команда 1 (Рябошапко Арсен / Олейник Юрій Валерійович) | U9: =IF(AND(ISNUMBER(P9),ISNUMBER(R9)),"Завершено","Очікується") -> Завершено | V9: 🥉 Бронзовий призер
M11: ФІНАЛ | N11: Золото | O11: =IF(T6="—","Переможець ПФ 1",T6) -> Команда 5 (Бичков Олег Володимирович / Пархоменко Максим Миколайович) | P11: 7 | Q11: : | R11: 11 | S11: =IF(T7="—","Переможець ПФ 2",T7) -> Команда 6 (Довгань Олександр / Катеринич Олександр Олександрович) | T11: =IF(AND(ISNUMBER(P11),ISNUMBER(R11)),IF(P11>R11,O11,IF(R11>P11,S11,"Нічия")),"—") -> Команда 6 (Довгань Олександр / Катеринич Олександр Олександрович) | U11: =IF(AND(ISNUMBER(P11),ISNUMBER(R11)),"Завершено","Очікується") -> Завершено | V11: 🏆 ЧЕМПІОН ТУРНІРУ
B12: ТАБЛИЦЯ ГРУПИ 2
B13: № | C13: Команда (Пара) | D13: Ігри | E13: В | F13: П | G13: Очки (+) | H13: Очки (-) | I13: Різниця (±) | J13: Місце
B14: 1 | C14: ="Команда 2 (" & 'Группа 1'!E10 & " / " & 'Группа 1'!E11 & ")" -> Команда 2 (Кухаренко Олександр / Васильєв Олексій Михайлович) | D14: =COUNTIFS($C$32:$C$37, C14, $I$32:$I$37, "Завершено") + COUNTIFS($G$32:$G$37, C14, $I$32:$I$37, "Завершено") -> 3 | E14: =COUNTIF($H$32:$H$37, C14) -> 0 | F14: =D14 - E14 -> 3 | G14: =SUMIF($C$32:$C$37, C14, $D$32:$D$37) + SUMIF($G$32:$G$37, C14, $F$32:$F$37) -> 9 | H14: =SUMIF($C$32:$C$37, C14, $F$32:$F$37) + SUMIF($G$32:$G$37, C14, $D$32:$D$37) -> 33 | I14: =G14 - H14 -> -24 | J14: =IF(SUM($D$14:$D$17)=0, "—", 1 + COUNTIFS($E$14:$E$17, ">"&E14) + COUNTIFS($E$14:$E$17, E14, $I$14:$I$17, ">"&I14) + COUNTIFS($E$14:$E$17, E14, $I$14:$I$17, I14, $G$14:$G$17, ">"&G14)) -> 4 | M14: РЕГЛАМЕНТ ПЛЕЙ-ОФ ТА СИСТЕМА ВИЗНАЧЕННЯ МІСЦЬ
B15: 2 | C15: ="Команда 5 (" & 'Группа 1'!E12 & " / " & 'Группа 1'!E13 & ")" -> Команда 5 (Бичков Олег Володимирович / Пархоменко Максим Миколайович) | D15: =COUNTIFS($C$32:$C$37, C15, $I$32:$I$37, "Завершено") + COUNTIFS($G$32:$G$37, C15, $I$32:$I$37, "Завершено") -> 3 | E15: =COUNTIF($H$32:$H$37, C15) -> 2 | F15: =D15 - E15 -> 1 | G15: =SUMIF($C$32:$C$37, C15, $D$32:$D$37) + SUMIF($G$32:$G$37, C15, $F$32:$F$37) -> 26 | H15: =SUMIF($C$32:$C$37, C15, $F$32:$F$37) + SUMIF($G$32:$G$37, C15, $D$32:$D$37) -> 19 | I15: =G15 - H15 -> 7 | J15: =IF(SUM($D$14:$D$17)=0, "—", 1 + COUNTIFS($E$14:$E$17, ">"&E15) + COUNTIFS($E$14:$E$17, E15, $I$14:$I$17, ">"&I15) + COUNTIFS($E$14:$E$17, E15, $I$14:$I$17, I15, $G$14:$G$17, ">"&G15)) -> 2 | M15: • 1/2 Фіналу: 1-ше місце Групи 1 грає проти 2-го місця Групи 2 (ПФ 1), а 1-ше місце Групи 2 — проти 2-го місця Групи 1 (ПФ 2)
B16: 3 | C16: ="Команда 6 (" & 'Группа 1'!E14 & " / " & 'Группа 1'!E15 & ")" -> Команда 6 (Довгань Олександр / Катеринич Олександр Олександрович) | D16: =COUNTIFS($C$32:$C$37, C16, $I$32:$I$37, "Завершено") + COUNTIFS($G$32:$G$37, C16, $I$32:$I$37, "Завершено") -> 3 | E16: =COUNTIF($H$32:$H$37, C16) -> 2 | F16: =D16 - E16 -> 1 | G16: =SUMIF($C$32:$C$37, C16, $D$32:$D$37) + SUMIF($G$32:$G$37, C16, $F$32:$F$37) -> 30 | H16: =SUMIF($C$32:$C$37, C16, $F$32:$F$37) + SUMIF($G$32:$G$37, C16, $D$32:$D$37) -> 19 | I16: =G16 - H16 -> 11 | J16: =IF(SUM($D$14:$D$17)=0, "—", 1 + COUNTIFS($E$14:$E$17, ">"&E16) + COUNTIFS($E$14:$E$17, E16, $I$14:$I$17, ">"&I16) + COUNTIFS($E$14:$E$17, E16, $I$14:$I$17, I16, $G$14:$G$17, ">"&G16)) -> 1 | M16: • Фінал: Переможці ПФ 1 та ПФ 2 змагаються за 1-ше місце (Золото) та титул Чемпіона турніру
B17: 4 | C17: ="Команда 8 (" & 'Группа 1'!E16 & " / " & 'Группа 1'!E17 & ")" -> Команда 8 (Зімін Михайло Володимирович / Папуров Григорій Георгійович) | D17: =COUNTIFS($C$32:$C$37, C17, $I$32:$I$37, "Завершено") + COUNTIFS($G$32:$G$37, C17, $I$32:$I$37, "Завершено") -> 3 | E17: =COUNTIF($H$32:$H$37, C17) -> 2 | F17: =D17 - E17 -> 1 | G17: =SUMIF($C$32:$C$37, C17, $D$32:$D$37) + SUMIF($G$32:$G$37, C17, $F$32:$F$37) -> 27 | H17: =SUMIF($C$32:$C$37, C17, $F$32:$F$37) + SUMIF($G$32:$G$37, C17, $D$32:$D$37) -> 21 | I17: =G17 - H17 -> 6 | J17: =IF(SUM($D$14:$D$17)=0, "—", 1 + COUNTIFS($E$14:$E$17, ">"&E17) + COUNTIFS($E$14:$E$17, E17, $I$14:$I$17, ">"&I17) + COUNTIFS($E$14:$E$17, E17, $I$14:$I$17, I17, $G$14:$G$17, ">"&G17)) -> 3 | M17: • Матч за 3-тє місце: Команди, які поступилися у півфіналах, розігрують комплект бронзових нагород
B18: * 1-2 місця кожної групи виходять до 1/2 фіналу Play-Off | M18: • Критерії розподілу місць у групах: 1) Кількість перемог (В); 2) Різниця очок (±); 3) Загальна кількість набраних очок (+)
M19: • Рахунок матчів вводиться у світло-жовті комірки стовпчиків «Очки 1» та «Очки 2»
B21: РОЗКЛАД ТА РЕЗУЛЬТАТИ МАТЧІВ — ГРУПА 1
B22: Матч | C22: Команда 1 | D22: Очки 1 | E22: : | F22: Очки 2 | G22: Команда 2 | H22: Переможець матчу | I22: Статус | J22: Різниця
B23: Тур 1 • М1 | C23: =C6 -> Команда 1 (Рябошапко Арсен / Олейник Юрій Валерійович) | D23: 11 | E23: : | F23: 2 | G23: =C7 -> Команда 3 (Кутовой Антон / Куліков Євген Олександрович) | H23: =IF(OR(ISBLANK(D23),ISBLANK(F23)),"—",IF(D23>F23,C23,IF(F23>D23,G23,"Нічия"))) -> Команда 1 (Рябошапко Арсен / Олейник Юрій Валерійович) | I23: =IF(OR(ISBLANK(D23),ISBLANK(F23)),"Очікується","Завершено") -> Завершено | J23: =IF(OR(ISBLANK(D23),ISBLANK(F23)),"—",ABS(D23-F23)) -> 9
B24: Тур 1 • М2 | C24: =C8 -> Команда 4 (Барбінягра Олександр Іванович / Лапшинський Олександр Анатолійович) | D24: 11 | E24: : | F24: 2 | G24: =C9 -> Команда 7 (Лещенко Валентин Валерійович / Москалюк Вадим Васильович) | H24: =IF(OR(ISBLANK(D24),ISBLANK(F24)),"—",IF(D24>F24,C24,IF(F24>D24,G24,"Нічия"))) -> Команда 4 (Барбінягра Олександр Іванович / Лапшинський Олександр Анатолійович) | I24: =IF(OR(ISBLANK(D24),ISBLANK(F24)),"Очікується","Завершено") -> Завершено | J24: =IF(OR(ISBLANK(D24),ISBLANK(F24)),"—",ABS(D24-F24)) -> 9
B25: Тур 2 • М3 | C25: =C6 -> Команда 1 (Рябошапко Арсен / Олейник Юрій Валерійович) | D25: 11 | E25: : | F25: 3 | G25: =C8 -> Команда 4 (Барбінягра Олександр Іванович / Лапшинський Олександр Анатолійович) | H25: =IF(OR(ISBLANK(D25),ISBLANK(F25)),"—",IF(D25>F25,C25,IF(F25>D25,G25,"Нічия"))) -> Команда 1 (Рябошапко Арсен / Олейник Юрій Валерійович) | I25: =IF(OR(ISBLANK(D25),ISBLANK(F25)),"Очікується","Завершено") -> Завершено | J25: =IF(OR(ISBLANK(D25),ISBLANK(F25)),"—",ABS(D25-F25)) -> 8
B26: Тур 2 • М4 | C26: =C7 -> Команда 3 (Кутовой Антон / Куліков Євген Олександрович) | D26: 11 | E26: : | F26: 2 | G26: =C9 -> Команда 7 (Лещенко Валентин Валерійович / Москалюк Вадим Васильович) | H26: =IF(OR(ISBLANK(D26),ISBLANK(F26)),"—",IF(D26>F26,C26,IF(F26>D26,G26,"Нічия"))) -> Команда 3 (Кутовой Антон / Куліков Євген Олександрович) | I26: =IF(OR(ISBLANK(D26),ISBLANK(F26)),"Очікується","Завершено") -> Завершено | J26: =IF(OR(ISBLANK(D26),ISBLANK(F26)),"—",ABS(D26-F26)) -> 9
B27: Тур 3 • М5 | C27: =C6 -> Команда 1 (Рябошапко Арсен / Олейник Юрій Валерійович) | D27: 11 | E27: : | F27: 2 | G27: =C9 -> Команда 7 (Лещенко Валентин Валерійович / Москалюк Вадим Васильович) | H27: =IF(OR(ISBLANK(D27),ISBLANK(F27)),"—",IF(D27>F27,C27,IF(F27>D27,G27,"Нічия"))) -> Команда 1 (Рябошапко Арсен / Олейник Юрій Валерійович) | I27: =IF(OR(ISBLANK(D27),ISBLANK(F27)),"Очікується","Завершено") -> Завершено | J27: =IF(OR(ISBLANK(D27),ISBLANK(F27)),"—",ABS(D27-F27)) -> 9
B28: Тур 3 • М6 | C28: =C7 -> Команда 3 (Кутовой Антон / Куліков Євген Олександрович) | D28: 11 | E28: : | F28: 9 | G28: =C8 -> Команда 4 (Барбінягра Олександр Іванович / Лапшинський Олександр Анатолійович) | H28: =IF(OR(ISBLANK(D28),ISBLANK(F28)),"—",IF(D28>F28,C28,IF(F28>D28,G28,"Нічия"))) -> Команда 3 (Кутовой Антон / Куліков Євген Олександрович) | I28: =IF(OR(ISBLANK(D28),ISBLANK(F28)),"Очікується","Завершено") -> Завершено | J28: =IF(OR(ISBLANK(D28),ISBLANK(F28)),"—",ABS(D28-F28)) -> 2 | M28: ПРИЗЕРИ ТУРНІРУ (ГРУПА 1)
M29: Місце | N29: Нагорода | O29: Команда (Призер)
B30: РОЗКЛАД ТА РЕЗУЛЬТАТИ МАТЧІВ — ГРУПА 2 | M30: 🥇 1-ше місце | N30: Золото | O30: =IF(T11="—","Визначається у фіналі",T11) -> Команда 6 (Довгань Олександр / Катеринич Олександр Олександрович)
B31: Матч | C31: Команда 1 | D31: Очки 1 | E31: : | F31: Очки 2 | G31: Команда 2 | H31: Переможець матчу | I31: Статус | J31: Різниця | M31: 🥈 2-ге місце | N31: Срібло | O31: =IF(AND(ISNUMBER(P11),ISNUMBER(R11)),IF(P11<R11,O11,S11),"Визначається у фіналі") -> Команда 5 (Бичков Олег Володимирович / Пархоменко Максим Миколайович)
B32: Тур 1 • М7 | C32: =C14 -> Команда 2 (Кухаренко Олександр / Васильєв Олексій Михайлович) | D32: 3 | E32: : | F32: 11 | G32: =C15 -> Команда 5 (Бичков Олег Володимирович / Пархоменко Максим Миколайович) | H32: =IF(OR(ISBLANK(D32),ISBLANK(F32)),"—",IF(D32>F32,C32,IF(F32>D32,G32,"Нічия"))) -> Команда 5 (Бичков Олег Володимирович / Пархоменко Максим Миколайович) | I32: =IF(OR(ISBLANK(D32),ISBLANK(F32)),"Очікується","Завершено") -> Завершено | J32: =IF(OR(ISBLANK(D32),ISBLANK(F32)),"—",ABS(D32-F32)) -> 8 | M32: 🥉 3-тє місце | N32: Бронза | O32: =IF(T9="—","Визначається у матчі за 3-тє місце",T9) -> Команда 1 (Рябошапко Арсен / Олейник Юрій Валерійович)
B33: Тур 1 • М8 | C33: =C16 -> Команда 6 (Довгань Олександр / Катеринич Олександр Олександрович) | D33: 8 | E33: : | F33: 11 | G33: =C17 -> Команда 8 (Зімін Михайло Володимирович / Папуров Григорій Георгійович) | H33: =IF(OR(ISBLANK(D33),ISBLANK(F33)),"—",IF(D33>F33,C33,IF(F33>D33,G33,"Нічия"))) -> Команда 8 (Зімін Михайло Володимирович / Папуров Григорій Георгійович) | I33: =IF(OR(ISBLANK(D33),ISBLANK(F33)),"Очікується","Завершено") -> Завершено | J33: =IF(OR(ISBLANK(D33),ISBLANK(F33)),"—",ABS(D33-F33)) -> 3
B34: Тур 2 • М9 | C34: =C14 -> Команда 2 (Кухаренко Олександр / Васильєв Олексій Михайлович) | D34: 4 | E34: : | F34: 11 | G34: =C16 -> Команда 6 (Довгань Олександр / Катеринич Олександр Олександрович) | H34: =IF(OR(ISBLANK(D34),ISBLANK(F34)),"—",IF(D34>F34,C34,IF(F34>D34,G34,"Нічия"))) -> Команда 6 (Довгань Олександр / Катеринич Олександр Олександрович) | I34: =IF(OR(ISBLANK(D34),ISBLANK(F34)),"Очікується","Завершено") -> Завершено | J34: =IF(OR(ISBLANK(D34),ISBLANK(F34)),"—",ABS(D34-F34)) -> 7
B35: Тур 2 • М10 | C35: =C15 -> Команда 5 (Бичков Олег Володимирович / Пархоменко Максим Миколайович) | D35: 11 | E35: : | F35: 5 | G35: =C17 -> Команда 8 (Зімін Михайло Володимирович / Папуров Григорій Георгійович) | H35: =IF(OR(ISBLANK(D35),ISBLANK(F35)),"—",IF(D35>F35,C35,IF(F35>D35,G35,"Нічия"))) -> Команда 5 (Бичков Олег Володимирович / Пархоменко Максим Миколайович) | I35: =IF(OR(ISBLANK(D35),ISBLANK(F35)),"Очікується","Завершено") -> Завершено | J35: =IF(OR(ISBLANK(D35),ISBLANK(F35)),"—",ABS(D35-F35)) -> 6
B36: Тур 3 • М11 | C36: =C14 -> Команда 2 (Кухаренко Олександр / Васильєв Олексій Михайлович) | D36: 2 | E36: : | F36: 11 | G36: =C17 -> Команда 8 (Зімін Михайло Володимирович / Папуров Григорій Георгійович) | H36: =IF(OR(ISBLANK(D36),ISBLANK(F36)),"—",IF(D36>F36,C36,IF(F36>D36,G36,"Нічия"))) -> Команда 8 (Зімін Михайло Володимирович / Папуров Григорій Георгійович) | I36: =IF(OR(ISBLANK(D36),ISBLANK(F36)),"Очікується","Завершено") -> Завершено | J36: =IF(OR(ISBLANK(D36),ISBLANK(F36)),"—",ABS(D36-F36)) -> 9
B37: Тур 3 • М12 | C37: =C15 -> Команда 5 (Бичков Олег Володимирович / Пархоменко Максим Миколайович) | D37: 4 | E37: : | F37: 11 | G37: =C16 -> Команда 6 (Довгань Олександр / Катеринич Олександр Олександрович) | H37: =IF(OR(ISBLANK(D37),ISBLANK(F37)),"—",IF(D37>F37,C37,IF(F37>D37,G37,"Нічия"))) -> Команда 6 (Довгань Олександр / Катеринич Олександр Олександрович) | I37: =IF(OR(ISBLANK(D37),ISBLANK(F37)),"Очікується","Завершено") -> Завершено | J37: =IF(OR(ISBLANK(D37),ISBLANK(F37)),"—",ABS(D37-F37)) -> 7 | O37: Команда 1 (Рябошапко Арсен / Олейник Юрій Валерійович) | Q37: : | S37: Команда 5 (Бичков Олег Володимирович / Пархоменко Максим Миколайович)
O41: Команда 6 (Довгань Олександр / Катеринич Олександр Олександрович) | Q41: 11 | R41: 1 | S41: Команда 3 (Кутовой Антон / Куліков Євген Олександрович)
Q42: 11 | R42: 2
C46: Команда 4 (Барбінягра Олександр Іванович / Лапшинський Олександр Анатолійович) | D46: 6 | F46: 11 | G46: Команда 2 (Кухаренко Олександр / Васильєв Олексій Михайлович) | O46: Команда 1 (Рябошапко Арсен / Олейник Юрій Валерійович) | S46: Команда 3 (Кутовой Антон / Куліков Євген Олександрович)
C47: Команда 8 (Зімін Михайло Володимирович / Папуров Григорій Георгійович) | G47: Команда 7 (Лещенко Валентин Валерійович / Москалюк Вадим Васильович)
O48: Команда 5 (Бичков Олег Володимирович / Пархоменко Максим Миколайович) | Q48: 7 | R48: 11 | S48: Команда 6 (Довгань Олександр / Катеринич Олександр Олександрович)

Sheet Группа 2
C1: Группа | D1: Команда | E1: Игрок
A2: 11 | B2: 46287.766 | C2: 1 | D2: 3 | E2: Концевой Сергій Миколайович | F2: 1 | G2: ТАК | H2: Ветерани з невидимими травмами | K2: ТАК
A3: 6 | B3: 46286.452 | C3: 1 | D3: 3.2 | E3: Парфенюк Сергій Олександрович | F3: 1 | G3: ТАК | H3: Ветерани з невидимими травмами | K3: ТАК
C4: 1 | D4: 11 | E4: Пазиніч Сергій Анатолійович
A5: 15 | B5: 46288.601 | C5: 1 | D5: 11.2 | E5: Олейник Юрій Валерійович | F5: 1 | G5: ТАК | H5: Ветерани з невидимими травмами | K5: ТАК
A6: 29 | B6: 46291.78 | C6: 1 | D6: 12 | E6: Делігіоз Андрій Георгійович | F6: 1 | G6: ТАК | H6: Ветерани з невидимими травмами | K6: ТАК
C7: 1 | D7: 12.2 | E7: Цап Олег
C8: 1 | D8: 13 | E8: Фещук Данило Олександрович
C9: 1 | D9: 13.2 | E9: Гиряк Роман Михайлович
A10: 49 | B10: 46299.85 | C10: 2 | D10: 4 | E10: Тарарака Олексій Борисович | F10: 1 | G10: ТАК | H10: Ветерани з невидимими травмами | K10: ТАК
A11: 13 | B11: 46288.527 | C11: 2 | D11: 4.2 | E11: Татаров Руслан Сергійович | F11: 1 | G11: ТАК | H11: Ветерани з невидимими травмами | K11: ТАК
A12: 19 | B12: 46289.396 | C12: 2 | D12: 7 | E12: Орєшин Микола Семенович | F12: 1 | G12: ТАК | H12: Ветерани з невидимими травмами | K12: ТАК
A13: 22 | B13: 46289.523 | C13: 2 | D13: 7.2 | E13: Грибонос Олександр Володиморович | F13: 1 | G13: ТАК | H13: Ветерани з невидимими травмами | K13: ТАК
A14: 36 | B14: 46296.491 | C14: 2 | D14: 9 | E14: Горковець Андрій Георгійович | F14: 1 | G14: ТАК | H14: Ветерани з невидимими травмами | K14: ТАК
A15: 37 | B15: 46296.497 | C15: 2 | D15: 9.2 | E15: Толкачов Сергій Вікторович | F15: 1 | G15: ТАК | H15: Ветерани з невидимими травмами | K15: ТАК
C16: 2 | D16: 14 | E16: Трач Ігор Іванович
A17: 5 | B17: 46286.424 | C17: 2 | D17: 14.2 | E17: Дучєв Максим Палович | F17: 1 | G17: ТАК | H17: Ветерани з невидимими травмами | K17: ТАК
A18: 30 | B18: 46292.654 | C18: 3 | D18: 2 | E18: Салабай Олександр | F18: 1 | G18: ТАК | H18: Ветерани без поранень | K18: ТАК
C19: 3 | D19: 2.2 | E19: Шульга Андрей | F19: 1 | G19: ТАК | H19: Ветерани без поранень
A20: 38 | B20: 46296.62 | C20: 3 | D20: 5 | E20: Прокопович Сергій Михайлович | F20: 1 | G20: ТАК | H20: Ветерани з невидимими травмами | K20: ТАК
A21: 1 | B21: 46286.383 | C21: 3 | D21: 5.2 | E21: Кравцов Олександр Сергійович | F21: 1 | G21: ТАК | H21: Ветерани з невидимими травмами | K21: ТАК
A22: 45 | B22: 46299.767 | C22: 3 | D22: 10 | E22: Кривонос Андрій Миколайович | F22: 1 | G22: ТАК | H22: Ветерани з невидимими травмами | K22: ТАК
C23: 3 | D23: 10.2 | E23: Мазур Володімір | H23: Єрмаков Володимир Володимирович
A24: 14 | B24: 46288.545 | C24: 4 | D24: 1 | E24: Сторожук Микола Миколайович | F24: 1 | G24: ТАК | H24: Ветерани з невидимими травмами | K24: ТАК
A25: 16 | B25: 46288.667 | C25: 4 | D25: 1.2 | E25: Нестерчук Вадим Миколайович | F25: 1 | G25: ТАК | H25: Ветерани з невидимими травмами | K25: ТАК
A26: 10 | B26: 46286.894 | C26: 4 | D26: 6 | E26: Глухов Андрій Валерійович | F26: 1 | G26: ТАК | H26: Ветерани без поранень | K26: ТАК
A27: 50 | B27: 46300.817 | C27: 4 | D27: 6.2 | E27: Змієвський Станіслав Валерійович | F27: 1 | G27: ТАК | H27: Ветерани з невидимими травмами | K27: ТАК
A28: 32 | B28: 46292.808 | C28: 4 | D28: 8 | E28: Камінський Владислав Олесьович | F28: 1 | G28: ТАК | H28: Ветерани з невидимими травмами | K28: ТАК
A29: 31 | B29: 46292.803 | C29: 4 | D29: 8.2 | E29: Дідик Сергій Станіславович | F29: 1 | G29: ТАК | H29: Ветерани з невидимими травмами | K29: ТАК
F225: 16
F226: 28
F227: 5
F229: 4
F231: 4 | G231: 14

Sheet Сетка Группа 2
B2: ТУРНІР З ПІКЛБОЛУ — ГРУПА 2 (ВЕТЕРАНИ)
B4: ТАБЛИЦЯ ГРУПИ 1 | L4: ФІНАЛЬНА СІТКА PLAY-OFF (1/4, 1/2 ФІНАЛУ ТА ФІНАЛИ)
B5: № | C5: Команда (Пара) | D5: Ігри | E5: В | F5: П | G5: Очки (+) | H5: Очки (-) | I5: Різниця (±) | J5: Місце | L5: Стадія | M5: Матч | N5: Команда 1 | O5: Очки 1 | P5: : | Q5: Очки 2 | R5: Команда 2 | S5: Переможець матчу | T5: Статус | U5: Примітка / Наступний етап
B6: 1 | C6: ="Команда 3 (" & 'Группа 2'!E2 & " / " & 'Группа 2'!E3 & ")" -> Команда 3 (Концевой Сергій Миколайович / Парфенюк Сергій Олександрович) | D6: =COUNTIFS($C$36:$C$41, C6, $I$36:$I$41, "Завершено") + COUNTIFS($G$36:$G$41, C6, $I$36:$I$41, "Завершено") -> 3 | E6: =COUNTIF($H$36:$H$41, C6) -> 3 | F6: =D6 - E6 -> 0 | G6: =SUMIF($C$36:$C$41, C6, $D$36:$D$41) + SUMIF($G$36:$G$41, C6, $F$36:$F$41) -> 33 | H6: =SUMIF($C$36:$C$41, C6, $F$36:$F$41) + SUMIF($G$36:$G$41, C6, $D$36:$D$41) -> 10 | I6: =G6 - H6 -> 23 | J6: =IF(SUM($D$6:$D$9)=0, "—", 1 + COUNTIFS($E$6:$E$9, ">"&E6) + COUNTIFS($E$6:$E$9, E6, $I$6:$I$9, ">"&I6) + COUNTIFS($E$6:$E$9, E6, $I$6:$I$9, I6, $G$6:$G$9, ">"&G6)) -> 1 | L6: 1/4 Фіналу | M6: ЧФ 1 | N6: {=IFERROR(INDEX($C$6:$C$9, MATCH(1, $J$6:$J$9, 0)), "1-ше місце Групи 1")} -> Команда 3 (Концевой Сергій Миколайович / Парфенюк Сергій Олександрович) | O6: 8 | P6: : | Q6: 11 | R6: {=IFERROR(INDEX($C$13:$C$16, MATCH(2, $J$13:$J$16, 0)), "2-ге місце Групи 2")} -> Команда 4 (Тарарака Олексій Борисович / Татаров Руслан Сергійович) | S6: =IF(AND(ISNUMBER(O6),ISNUMBER(Q6)),IF(O6>Q6,N6,IF(Q6>O6,R6,"Нічия")),"—") -> Команда 4 (Тарарака Олексій Борисович / Татаров Руслан Сергійович) | T6: =IF(AND(ISNUMBER(O6),ISNUMBER(Q6)),"Завершено","Очікується") -> Завершено | U6: Вихід до 1/2 фіналу
B7: 2 | C7: ="Команда 11 (" & 'Группа 2'!E4 & " / " & 'Группа 2'!E5 & ")" -> Команда 11 (Пазиніч Сергій Анатолійович / Олейник Юрій Валерійович) | D7: =COUNTIFS($C$36:$C$41, C7, $I$36:$I$41, "Завершено") + COUNTIFS($G$36:$G$41, C7, $I$36:$I$41, "Завершено") -> 3 | E7: =COUNTIF($H$36:$H$41, C7) -> 0 | F7: =D7 - E7 -> 3 | G7: =SUMIF($C$36:$C$41, C7, $D$36:$D$41) + SUMIF($G$36:$G$41, C7, $F$36:$F$41) -> 0 | H7: =SUMIF($C$36:$C$41, C7, $F$36:$F$41) + SUMIF($G$36:$G$41, C7, $D$36:$D$41) -> 33 | I7: =G7 - H7 -> -33 | J7: =IF(SUM($D$6:$D$9)=0, "—", 1 + COUNTIFS($E$6:$E$9, ">"&E7) + COUNTIFS($E$6:$E$9, E7, $I$6:$I$9, ">"&I7) + COUNTIFS($E$6:$E$9, E7, $I$6:$I$9, I7, $G$6:$G$9, ">"&G7)) -> 4 | L7: 1/4 Фіналу | M7: ЧФ 2 | N7: {=IFERROR(INDEX($C$20:$C$22, MATCH(1, $J$20:$J$22, 0)), "1-ше місце Групи 3")} -> Команда 2 (Салабай Олександр / Шульга Андрей) | O7: 11 | P7: : | Q7: 2 | R7: {=IFERROR(INDEX($C$26:$C$28, MATCH(2, $J$26:$J$28, 0)), "2-ге місце Групи 4")} -> Команда 6 (Глухов Андрій Валерійович / Змієвський Станіслав Валерійович) | S7: =IF(AND(ISNUMBER(O7),ISNUMBER(Q7)),IF(O7>Q7,N7,IF(Q7>O7,R7,"Нічия")),"—") -> Команда 2 (Салабай Олександр / Шульга Андрей) | T7: =IF(AND(ISNUMBER(O7),ISNUMBER(Q7)),"Завершено","Очікується") -> Завершено | U7: Вихід до 1/2 фіналу
B8: 3 | C8: ="Команда 12 (" & 'Группа 2'!E6 & " / " & 'Группа 2'!E7 & ")" -> Команда 12 (Делігіоз Андрій Георгійович / Цап Олег) | D8: =COUNTIFS($C$36:$C$41, C8, $I$36:$I$41, "Завершено") + COUNTIFS($G$36:$G$41, C8, $I$36:$I$41, "Завершено") -> 3 | E8: =COUNTIF($H$36:$H$41, C8) -> 1 | F8: =D8 - E8 -> 2 | G8: =SUMIF($C$36:$C$41, C8, $D$36:$D$41) + SUMIF($G$36:$G$41, C8, $F$36:$F$41) -> 14 | H8: =SUMIF($C$36:$C$41, C8, $F$36:$F$41) + SUMIF($G$36:$G$41, C8, $D$36:$D$41) -> 22 | I8: =G8 - H8 -> -8 | J8: =IF(SUM($D$6:$D$9)=0, "—", 1 + COUNTIFS($E$6:$E$9, ">"&E8) + COUNTIFS($E$6:$E$9, E8, $I$6:$I$9, ">"&I8) + COUNTIFS($E$6:$E$9, E8, $I$6:$I$9, I8, $G$6:$G$9, ">"&G8)) -> 3 | L8: 1/4 Фіналу | M8: ЧФ 3 | N8: {=IFERROR(INDEX($C$13:$C$16, MATCH(1, $J$13:$J$16, 0)), "1-ше місце Групи 2")} -> Команда 7 (Орєшин Микола Семенович / Грибонос Олександр Володиморович) | O8: 8 | P8: : | Q8: 11 | R8: {=IFERROR(INDEX($C$6:$C$9, MATCH(2, $J$6:$J$9, 0)), "2-ге місце Групи 1")} -> Команда 13 (Фещук Данило Олександрович / Гиряк Роман Михайлович) | S8: =IF(AND(ISNUMBER(O8),ISNUMBER(Q8)),IF(O8>Q8,N8,IF(Q8>O8,R8,"Нічия")),"—") -> Команда 13 (Фещук Данило Олександрович / Гиряк Роман Михайлович) | T8: =IF(AND(ISNUMBER(O8),ISNUMBER(Q8)),"Завершено","Очікується") -> Завершено | U8: Вихід до 1/2 фіналу
B9: 4 | C9: ="Команда 13 (" & 'Группа 2'!E8 & " / " & 'Группа 2'!E9 & ")" -> Команда 13 (Фещук Данило Олександрович / Гиряк Роман Михайлович) | D9: =COUNTIFS($C$36:$C$41, C9, $I$36:$I$41, "Завершено") + COUNTIFS($G$36:$G$41, C9, $I$36:$I$41, "Завершено") -> 3 | E9: =COUNTIF($H$36:$H$41, C9) -> 2 | F9: =D9 - E9 -> 1 | G9: =SUMIF($C$36:$C$41, C9, $D$36:$D$41) + SUMIF($G$36:$G$41, C9, $F$36:$F$41) -> 29 | H9: =SUMIF($C$36:$C$41, C9, $F$36:$F$41) + SUMIF($G$36:$G$41, C9, $D$36:$D$41) -> 11 | I9: =G9 - H9 -> 18 | J9: =IF(SUM($D$6:$D$9)=0, "—", 1 + COUNTIFS($E$6:$E$9, ">"&E9) + COUNTIFS($E$6:$E$9, E9, $I$6:$I$9, ">"&I9) + COUNTIFS($E$6:$E$9, E9, $I$6:$I$9, I9, $G$6:$G$9, ">"&G9)) -> 2 | L9: 1/4 Фіналу | M9: ЧФ 4 | N9: {=IFERROR(INDEX($C$26:$C$28, MATCH(1, $J$26:$J$28, 0)), "1-ше місце Групи 4")} -> Команда 1 (Сторожук Микола Миколайович / Нестерчук Вадим Миколайович) | O9: 11 | P9: : | Q9: 2 | R9: {=IFERROR(INDEX($C$20:$C$22, MATCH(2, $J$20:$J$22, 0)), "2-ге місце Групи 3")} -> Команда 5 (Прокопович Сергій Михайлович / Кравцов Олександр Сергійович) | S9: =IF(AND(ISNUMBER(O9),ISNUMBER(Q9)),IF(O9>Q9,N9,IF(Q9>O9,R9,"Нічия")),"—") -> Команда 1 (Сторожук Микола Миколайович / Нестерчук Вадим Миколайович) | T9: =IF(AND(ISNUMBER(O9),ISNUMBER(Q9)),"Завершено","Очікується") -> Завершено | U9: Вихід до 1/2 фіналу
B11: ТАБЛИЦЯ ГРУПИ 2 | L11: 1/2 Фіналу | M11: ПФ 1 | N11: =IF(S6="—","Переможець ЧФ 1",S6) -> Команда 4 (Тарарака Олексій Борисович / Татаров Руслан Сергійович) | O11: 7 | P11: : | Q11: 11 | R11: =IF(S7="—","Переможець ЧФ 2",S7) -> Команда 2 (Салабай Олександр / Шульга Андрей) | S11: =IF(AND(ISNUMBER(O11),ISNUMBER(Q11)),IF(O11>Q11,N11,IF(Q11>O11,R11,"Нічия")),"—") -> Команда 2 (Салабай Олександр / Шульга Андрей) | T11: =IF(AND(ISNUMBER(O11),ISNUMBER(Q11)),"Завершено","Очікується") -> Завершено | U11: Вихід до Фіналу
B12: № | C12: Команда (Пара) | D12: Ігри | E12: В | F12: П | G12: Очки (+) | H12: Очки (-) | I12: Різниця (±) | J12: Місце | L12: 1/2 Фіналу | M12: ПФ 2 | N12: =IF(S8="—","Переможець ЧФ 3",S8) -> Команда 13 (Фещук Данило Олександрович / Гиряк Роман Михайлович) | O12: 5 | P12: : | Q12: 11 | R12: =IF(S9="—","Переможець ЧФ 4",S9) -> Команда 1 (Сторожук Микола Миколайович / Нестерчук Вадим Миколайович) | S12: =IF(AND(ISNUMBER(O12),ISNUMBER(Q12)),IF(O12>Q12,N12,IF(Q12>O12,R12,"Нічия")),"—") -> Команда 1 (Сторожук Микола Миколайович / Нестерчук Вадим Миколайович) | T12: =IF(AND(ISNUMBER(O12),ISNUMBER(Q12)),"Завершено","Очікується") -> Завершено | U12: Вихід до Фіналу
B13: 1 | C13: ="Команда 4 (" & 'Группа 2'!E10 & " / " & 'Группа 2'!E11 & ")" -> Команда 4 (Тарарака Олексій Борисович / Татаров Руслан Сергійович) | D13: =COUNTIFS($C$45:$C$50, C13, $I$45:$I$50, "Завершено") + COUNTIFS($G$45:$G$50, C13, $I$45:$I$50, "Завершено") -> 3 | E13: =COUNTIF($H$45:$H$50, C13) -> 2 | F13: =D13 - E13 -> 1 | G13: =SUMIF($C$45:$C$50, C13, $D$45:$D$50) + SUMIF($G$45:$G$50, C13, $F$45:$F$50) -> 33 | H13: =SUMIF($C$45:$C$50, C13, $F$45:$F$50) + SUMIF($G$45:$G$50, C13, $D$45:$D$50) -> 13 | I13: =G13 - H13 -> 20 | J13: =IF(SUM($D$13:$D$16)=0, "—", 1 + COUNTIFS($E$13:$E$16, ">"&E13) + COUNTIFS($E$13:$E$16, E13, $I$13:$I$16, ">"&I13) + COUNTIFS($E$13:$E$16, E13, $I$13:$I$16, I13, $G$13:$G$16, ">"&G13)) -> 2
B14: 2 | C14: ="Команда 7 (" & 'Группа 2'!E12 & " / " & 'Группа 2'!E13 & ")" -> Команда 7 (Орєшин Микола Семенович / Грибонос Олександр Володиморович) | D14: =COUNTIFS($C$45:$C$50, C14, $I$45:$I$50, "Завершено") + COUNTIFS($G$45:$G$50, C14, $I$45:$I$50, "Завершено") -> 3 | E14: =COUNTIF($H$45:$H$50, C14) -> 3 | F14: =D14 - E14 -> 0 | G14: =SUMIF($C$45:$C$50, C14, $D$45:$D$50) + SUMIF($G$45:$G$50, C14, $F$45:$F$50) -> 35 | H14: =SUMIF($C$45:$C$50, C14, $F$45:$F$50) + SUMIF($G$45:$G$50, C14, $D$45:$D$50) -> 15 | I14: =G14 - H14 -> 20 | J14: =IF(SUM($D$13:$D$16)=0, "—", 1 + COUNTIFS($E$13:$E$16, ">"&E14) + COUNTIFS($E$13:$E$16, E14, $I$13:$I$16, ">"&I14) + COUNTIFS($E$13:$E$16, E14, $I$13:$I$16, I14, $G$13:$G$16, ">"&G14)) -> 1 | L14: Матч за 3 місце | M14: Бронза | N14: =IF(AND(ISNUMBER(O11),ISNUMBER(Q11)),IF(O11<Q11,N11,R11),"Програвший ПФ 1") -> Команда 4 (Тарарака Олексій Борисович / Татаров Руслан Сергійович) | O14: 11 | P14: : | Q14: 5 | R14: =IF(AND(ISNUMBER(O12),ISNUMBER(Q12)),IF(O12<Q12,N12,R12),"Програвший ПФ 2") -> Команда 13 (Фещук Данило Олександрович / Гиряк Роман Михайлович) | S14: =IF(AND(ISNUMBER(O14),ISNUMBER(Q14)),IF(O14>Q14,N14,IF(Q14>O14,R14,"Нічия")),"—") -> Команда 4 (Тарарака Олексій Борисович / Татаров Руслан Сергійович) | T14: =IF(AND(ISNUMBER(O14),ISNUMBER(Q14)),"Завершено","Очікується") -> Завершено | U14: 🥉 Бронзовий призер
B15: 3 | C15: ="Команда 9 (" & 'Группа 2'!E14 & " / " & 'Группа 2'!E15 & ")" -> Команда 9 (Горковець Андрій Георгійович / Толкачов Сергій Вікторович) | D15: =COUNTIFS($C$45:$C$50, C15, $I$45:$I$50, "Завершено") + COUNTIFS($G$45:$G$50, C15, $I$45:$I$50, "Завершено") -> 3 | E15: =COUNTIF($H$45:$H$50, C15) -> 0 | F15: =D15 - E15 -> 3 | G15: =SUMIF($C$45:$C$50, C15, $D$45:$D$50) + SUMIF($G$45:$G$50, C15, $F$45:$F$50) -> 0 | H15: =SUMIF($C$45:$C$50, C15, $F$45:$F$50) + SUMIF($G$45:$G$50, C15, $D$45:$D$50) -> 33 | I15: =G15 - H15 -> -33 | J15: =IF(SUM($D$13:$D$16)=0, "—", 1 + COUNTIFS($E$13:$E$16, ">"&E15) + COUNTIFS($E$13:$E$16, E15, $I$13:$I$16, ">"&I15) + COUNTIFS($E$13:$E$16, E15, $I$13:$I$16, I15, $G$13:$G$16, ">"&G15)) -> 4
B16: 4 | C16: ="Команда 14 (" & 'Группа 2'!E16 & " / " & 'Группа 2'!E17 & ")" -> Команда 14 (Трач Ігор Іванович / Дучєв Максим Палович) | D16: =COUNTIFS($C$45:$C$50, C16, $I$45:$I$50, "Завершено") + COUNTIFS($G$45:$G$50, C16, $I$45:$I$50, "Завершено") -> 3 | E16: =COUNTIF($H$45:$H$50, C16) -> 1 | F16: =D16 - E16 -> 2 | G16: =SUMIF($C$45:$C$50, C16, $D$45:$D$50) + SUMIF($G$45:$G$50, C16, $F$45:$F$50) -> 15 | H16: =SUMIF($C$45:$C$50, C16, $F$45:$F$50) + SUMIF($G$45:$G$50, C16, $D$45:$D$50) -> 22 | I16: =G16 - H16 -> -7 | J16: =IF(SUM($D$13:$D$16)=0, "—", 1 + COUNTIFS($E$13:$E$16, ">"&E16) + COUNTIFS($E$13:$E$16, E16, $I$13:$I$16, ">"&I16) + COUNTIFS($E$13:$E$16, E16, $I$13:$I$16, I16, $G$13:$G$16, ">"&G16)) -> 3 | L16: ФІНАЛ | M16: Золото | N16: =IF(S11="—","Переможець ПФ 1",S11) -> Команда 2 (Салабай Олександр / Шульга Андрей) | O16: 11 | P16: : | Q16: 8 | R16: =IF(S12="—","Переможець ПФ 2",S12) -> Команда 1 (Сторожук Микола Миколайович / Нестерчук Вадим Миколайович) | S16: =IF(AND(ISNUMBER(O16),ISNUMBER(Q16)),IF(O16>Q16,N16,IF(Q16>O16,R16,"Нічия")),"—") -> Команда 2 (Салабай Олександр / Шульга Андрей) | T16: =IF(AND(ISNUMBER(O16),ISNUMBER(Q16)),"Завершено","Очікується") -> Завершено | U16: 🏆 ЧЕМПІОН ТУРНІРУ
B18: ТАБЛИЦЯ ГРУПИ 3 | L18: РЕГЛАМЕНТ ПЛЕЙ-ОФ ТА СИСТЕМА ВИЗНАЧЕННЯ МІСЦЬ
B19: № | C19: Команда (Пара) | D19: Ігри | E19: В | F19: П | G19: Очки (+) | H19: Очки (-) | I19: Різниця (±) | J19: Місце | L19: • 1/4 Фіналу: 1-ші місця груп грають проти 2-х місць інших груп (1A-2B, 1C-2D, 1B-2A, 1D-2C)
B20: 1 | C20: ="Команда 2 (" & 'Группа 2'!E18 & " / " & 'Группа 2'!E19 & ")" -> Команда 2 (Салабай Олександр / Шульга Андрей) | D20: =COUNTIFS($C$54:$C$56, C20, $I$54:$I$56, "Завершено") + COUNTIFS($G$54:$G$56, C20, $I$54:$I$56, "Завершено") -> 2 | E20: =COUNTIF($H$54:$H$56, C20) -> 2 | F20: =D20 - E20 -> 0 | G20: =SUMIF($C$54:$C$56, C20, $D$54:$D$56) + SUMIF($G$54:$G$56, C20, $F$54:$F$56) -> 22 | H20: =SUMIF($C$54:$C$56, C20, $F$54:$F$56) + SUMIF($G$54:$G$56, C20, $D$54:$D$56) -> 5 | I20: =G20 - H20 -> 17 | J20: =IF(SUM($D$20:$D$22)=0, "—", 1 + COUNTIFS($E$20:$E$22, ">"&E20) + COUNTIFS($E$20:$E$22, E20, $I$20:$I$22, ">"&I20) + COUNTIFS($E$20:$E$22, E20, $I$20:$I$22, I20, $G$20:$G$22, ">"&G20)) -> 1 | L20: • 1/2 Фіналу: Переможці ЧФ 1 та ЧФ 2 формують ПФ 1, переможці ЧФ 3 та ЧФ 4 формують ПФ 2
B21: 2 | C21: ="Команда 5 (" & 'Группа 2'!E20 & " / " & 'Группа 2'!E21 & ")" -> Команда 5 (Прокопович Сергій Михайлович / Кравцов Олександр Сергійович) | D21: =COUNTIFS($C$54:$C$56, C21, $I$54:$I$56, "Завершено") + COUNTIFS($G$54:$G$56, C21, $I$54:$I$56, "Завершено") -> 2 | E21: =COUNTIF($H$54:$H$56, C21) -> 1 | F21: =D21 - E21 -> 1 | G21: =SUMIF($C$54:$C$56, C21, $D$54:$D$56) + SUMIF($G$54:$G$56, C21, $F$54:$F$56) -> 16 | H21: =SUMIF($C$54:$C$56, C21, $F$54:$F$56) + SUMIF($G$54:$G$56, C21, $D$54:$D$56) -> 13 | I21: =G21 - H21 -> 3 | J21: =IF(SUM($D$20:$D$22)=0, "—", 1 + COUNTIFS($E$20:$E$22, ">"&E21) + COUNTIFS($E$20:$E$22, E21, $I$20:$I$22, ">"&I21) + COUNTIFS($E$20:$E$22, E21, $I$20:$I$22, I21, $G$20:$G$22, ">"&G21)) -> 2 | L21: • Фінал: Переможці ПФ 1 та ПФ 2 змагаються за 1-ше місце (Золото) та титул Чемпіона турніру
B22: 3 | C22: ="Команда 10 (" & 'Группа 2'!E22 & " / " & 'Группа 2'!E23 & ")" -> Команда 10 (Кривонос Андрій Миколайович / Мазур Володімір) | D22: =COUNTIFS($C$54:$C$56, C22, $I$54:$I$56, "Завершено") + COUNTIFS($G$54:$G$56, C22, $I$54:$I$56, "Завершено") -> 2 | E22: =COUNTIF($H$54:$H$56, C22) -> 0 | F22: =D22 - E22 -> 2 | G22: =SUMIF($C$54:$C$56, C22, $D$54:$D$56) + SUMIF($G$54:$G$56, C22, $F$54:$F$56) -> 2 | H22: =SUMIF($C$54:$C$56, C22, $F$54:$F$56) + SUMIF($G$54:$G$56, C22, $D$54:$D$56) -> 22 | I22: =G22 - H22 -> -20 | J22: =IF(SUM($D$20:$D$22)=0, "—", 1 + COUNTIFS($E$20:$E$22, ">"&E22) + COUNTIFS($E$20:$E$22, E22, $I$20:$I$22, ">"&I22) + COUNTIFS($E$20:$E$22, E22, $I$20:$I$22, I22, $G$20:$G$22, ">"&G22)) -> 3 | L22: • Матч за 3-тє місце: Команди, які поступилися у півфіналах, розігрують комплект бронзових нагород
L23: • Критерії розподілу місць у групах: 1) Кількість перемог (В); 2) Різниця очок (±); 3) Загальна кількість набраних очок (+)
B24: ТАБЛИЦЯ ГРУПИ 4 | L24: • Рахунок матчів вводиться у світло-жовті комірки стовпчиків «Очки 1» та «Очки 2»
B25: № | C25: Команда (Пара) | D25: Ігри | E25: В | F25: П | G25: Очки (+) | H25: Очки (-) | I25: Різниця (±) | J25: Місце
B26: 1 | C26: ="Команда 1 (" & 'Группа 2'!E24 & " / " & 'Группа 2'!E25 & ")" -> Команда 1 (Сторожук Микола Миколайович / Нестерчук Вадим Миколайович) | D26: =COUNTIFS($C$60:$C$62, C26, $I$60:$I$62, "Завершено") + COUNTIFS($G$60:$G$62, C26, $I$60:$I$62, "Завершено") -> 2 | E26: =COUNTIF($H$60:$H$62, C26) -> 2 | F26: =D26 - E26 -> 0 | G26: =SUMIF($C$60:$C$62, C26, $D$60:$D$62) + SUMIF($G$60:$G$62, C26, $F$60:$F$62) -> 22 | H26: =SUMIF($C$60:$C$62, C26, $F$60:$F$62) + SUMIF($G$60:$G$62, C26, $D$60:$D$62) -> 7 | I26: =G26 - H26 -> 15 | J26: =IF(SUM($D$26:$D$28)=0, "—", 1 + COUNTIFS($E$26:$E$28, ">"&E26) + COUNTIFS($E$26:$E$28, E26, $I$26:$I$28, ">"&I26) + COUNTIFS($E$26:$E$28, E26, $I$26:$I$28, I26, $G$26:$G$28, ">"&G26)) -> 1
B27: 2 | C27: ="Команда 6 (" & 'Группа 2'!E26 & " / " & 'Группа 2'!E27 & ")" -> Команда 6 (Глухов Андрій Валерійович / Змієвський Станіслав Валерійович) | D27: =COUNTIFS($C$60:$C$62, C27, $I$60:$I$62, "Завершено") + COUNTIFS($G$60:$G$62, C27, $I$60:$I$62, "Завершено") -> 2 | E27: =COUNTIF($H$60:$H$62, C27) -> 1 | F27: =D27 - E27 -> 1 | G27: =SUMIF($C$60:$C$62, C27, $D$60:$D$62) + SUMIF($G$60:$G$62, C27, $F$60:$F$62) -> 13 | H27: =SUMIF($C$60:$C$62, C27, $F$60:$F$62) + SUMIF($G$60:$G$62, C27, $D$60:$D$62) -> 13 | I27: =G27 - H27 -> 0 | J27: =IF(SUM($D$26:$D$28)=0, "—", 1 + COUNTIFS($E$26:$E$28, ">"&E27) + COUNTIFS($E$26:$E$28, E27, $I$26:$I$28, ">"&I27) + COUNTIFS($E$26:$E$28, E27, $I$26:$I$28, I27, $G$26:$G$28, ">"&G27)) -> 2
B28: 3 | C28: ="Команда 8 (" & 'Группа 2'!E28 & " / " & 'Группа 2'!E29 & ")" -> Команда 8 (Камінський Владислав Олесьович / Дідик Сергій Станіславович) | D28: =COUNTIFS($C$60:$C$62, C28, $I$60:$I$62, "Завершено") + COUNTIFS($G$60:$G$62, C28, $I$60:$I$62, "Завершено") -> 2 | E28: =COUNTIF($H$60:$H$62, C28) -> 0 | F28: =D28 - E28 -> 2 | G28: =SUMIF($C$60:$C$62, C28, $D$60:$D$62) + SUMIF($G$60:$G$62, C28, $F$60:$F$62) -> 7 | H28: =SUMIF($C$60:$C$62, C28, $F$60:$F$62) + SUMIF($G$60:$G$62, C28, $D$60:$D$62) -> 22 | I28: =G28 - H28 -> -15 | J28: =IF(SUM($D$26:$D$28)=0, "—", 1 + COUNTIFS($E$26:$E$28, ">"&E28) + COUNTIFS($E$26:$E$28, E28, $I$26:$I$28, ">"&I28) + COUNTIFS($E$26:$E$28, E28, $I$26:$I$28, I28, $G$26:$G$28, ">"&G28)) -> 3
B30: * 1-2 місця кожної групи виходять до 1/4 фіналу Play-Off | L30: ПРИЗЕРИ ТУРНІРУ (ГРУПА 2)
L31: Місце | M31: Нагорода | N31: Команда (Призер)
L32: 🥇 1-ше місце | M32: Золото | N32: =IF(S16="—","Визначається у фіналі",S16) -> Команда 2 (Салабай Олександр / Шульга Андрей)
L33: 🥈 2-ге місце | M33: Срібло | N33: =IF(AND(ISNUMBER(O16),ISNUMBER(Q16)),IF(O16<Q16,N16,R16),"Визначається у фіналі") -> Команда 1 (Сторожук Микола Миколайович / Нестерчук Вадим Миколайович)
B34: РОЗКЛАД ТА РЕЗУЛЬТАТИ МАТЧІВ — ГРУПА 1 | L34: 🥉 3-тє місце | M34: Бронза | N34: =IF(S14="—","Визначається у матчі за 3-тє місце",S14) -> Команда 4 (Тарарака Олексій Борисович / Татаров Руслан Сергійович)
B35: Матч | C35: Команда 1 | D35: Очки 1 | E35: : | F35: Очки 2 | G35: Команда 2 | H35: Переможець матчу | I35: Статус | J35: Різниця
B36: Тур 1 • М1 | C36: =C6 -> Команда 3 (Концевой Сергій Миколайович / Парфенюк Сергій Олександрович) | D36: 11 | E36: : | F36: 0 | G36: =C7 -> Команда 11 (Пазиніч Сергій Анатолійович / Олейник Юрій Валерійович) | H36: =IF(OR(ISBLANK(D36),ISBLANK(F36)),"—",IF(D36>F36,C36,IF(F36>D36,G36,"Нічия"))) -> Команда 3 (Концевой Сергій Миколайович / Парфенюк Сергій Олександрович) | I36: =IF(OR(ISBLANK(D36),ISBLANK(F36)),"Очікується","Завершено") -> Завершено | J36: =IF(OR(ISBLANK(D36),ISBLANK(F36)),"—",ABS(D36-F36)) -> 11
B37: Тур 1 • М2 | C37: =C8 -> Команда 12 (Делігіоз Андрій Георгійович / Цап Олег) | D37: 0 | E37: : | F37: 11 | G37: =C9 -> Команда 13 (Фещук Данило Олександрович / Гиряк Роман Михайлович) | H37: =IF(OR(ISBLANK(D37),ISBLANK(F37)),"—",IF(D37>F37,C37,IF(F37>D37,G37,"Нічия"))) -> Команда 13 (Фещук Данило Олександрович / Гиряк Роман Михайлович) | I37: =IF(OR(ISBLANK(D37),ISBLANK(F37)),"Очікується","Завершено") -> Завершено | J37: =IF(OR(ISBLANK(D37),ISBLANK(F37)),"—",ABS(D37-F37)) -> 11
B38: Тур 2 • М3 | C38: =C6 -> Команда 3 (Концевой Сергій Миколайович / Парфенюк Сергій Олександрович) | D38: 11 | E38: : | F38: 3 | G38: =C8 -> Команда 12 (Делігіоз Андрій Георгійович / Цап Олег) | H38: =IF(OR(ISBLANK(D38),ISBLANK(F38)),"—",IF(D38>F38,C38,IF(F38>D38,G38,"Нічия"))) -> Команда 3 (Концевой Сергій Миколайович / Парфенюк Сергій Олександрович) | I38: =IF(OR(ISBLANK(D38),ISBLANK(F38)),"Очікується","Завершено") -> Завершено | J38: =IF(OR(ISBLANK(D38),ISBLANK(F38)),"—",ABS(D38-F38)) -> 8
B39: Тур 2 • М4 | C39: =C7 -> Команда 11 (Пазиніч Сергій Анатолійович / Олейник Юрій Валерійович) | D39: 0 | E39: : | F39: 11 | G39: =C9 -> Команда 13 (Фещук Данило Олександрович / Гиряк Роман Михайлович) | H39: =IF(OR(ISBLANK(D39),ISBLANK(F39)),"—",IF(D39>F39,C39,IF(F39>D39,G39,"Нічия"))) -> Команда 13 (Фещук Данило Олександрович / Гиряк Роман Михайлович) | I39: =IF(OR(ISBLANK(D39),ISBLANK(F39)),"Очікується","Завершено") -> Завершено | J39: =IF(OR(ISBLANK(D39),ISBLANK(F39)),"—",ABS(D39-F39)) -> 11
B40: Тур 3 • М5 | C40: =C6 -> Команда 3 (Концевой Сергій Миколайович / Парфенюк Сергій Олександрович) | D40: 11 | E40: : | F40: 7 | G40: =C9 -> Команда 13 (Фещук Данило Олександрович / Гиряк Роман Михайлович) | H40: =IF(OR(ISBLANK(D40),ISBLANK(F40)),"—",IF(D40>F40,C40,IF(F40>D40,G40,"Нічия"))) -> Команда 3 (Концевой Сергій Миколайович / Парфенюк Сергій Олександрович) | I40: =IF(OR(ISBLANK(D40),ISBLANK(F40)),"Очікується","Завершено") -> Завершено | J40: =IF(OR(ISBLANK(D40),ISBLANK(F40)),"—",ABS(D40-F40)) -> 4
B41: Тур 3 • М6 | C41: =C7 -> Команда 11 (Пазиніч Сергій Анатолійович / Олейник Юрій Валерійович) | D41: 0 | E41: : | F41: 11 | G41: =C8 -> Команда 12 (Делігіоз Андрій Георгійович / Цап Олег) | H41: =IF(OR(ISBLANK(D41),ISBLANK(F41)),"—",IF(D41>F41,C41,IF(F41>D41,G41,"Нічия"))) -> Команда 12 (Делігіоз Андрій Георгійович / Цап Олег) | I41: =IF(OR(ISBLANK(D41),ISBLANK(F41)),"Очікується","Завершено") -> Завершено | J41: =IF(OR(ISBLANK(D41),ISBLANK(F41)),"—",ABS(D41-F41)) -> 11
B43: РОЗКЛАД ТА РЕЗУЛЬТАТИ МАТЧІВ — ГРУПА 2
B44: Матч | C44: Команда 1 | D44: Очки 1 | E44: : | F44: Очки 2 | G44: Команда 2 | H44: Переможець матчу | I44: Статус | J44: Різниця | N44: Команда 2 (Олександр Салабай / Шульга Андрей) | O44: 11 | Q44: 2 | R44: Команда 6 (Глухов Андрій Валерійович / Змієвський Станіслав Валерійович)
B45: Тур 1 • М7 | C45: =C13 -> Команда 4 (Тарарака Олексій Борисович / Татаров Руслан Сергійович) | D45: 11 | E45: : | F45: 13 | G45: =C14 -> Команда 7 (Орєшин Микола Семенович / Грибонос Олександр Володиморович) | H45: =IF(OR(ISBLANK(D45),ISBLANK(F45)),"—",IF(D45>F45,C45,IF(F45>D45,G45,"Нічия"))) -> Команда 7 (Орєшин Микола Семенович / Грибонос Олександр Володиморович) | I45: =IF(OR(ISBLANK(D45),ISBLANK(F45)),"Очікується","Завершено") -> Завершено | J45: =IF(OR(ISBLANK(D45),ISBLANK(F45)),"—",ABS(D45-F45)) -> 2 | O45: 11 | Q45: 4
B46: Тур 1 • М8 | C46: =C15 -> Команда 9 (Горковець Андрій Георгійович / Толкачов Сергій Вікторович) | D46: 0 | E46: : | F46: 11 | G46: =C16 -> Команда 14 (Трач Ігор Іванович / Дучєв Максим Палович) | H46: =IF(OR(ISBLANK(D46),ISBLANK(F46)),"—",IF(D46>F46,C46,IF(F46>D46,G46,"Нічия"))) -> Команда 14 (Трач Ігор Іванович / Дучєв Максим Палович) | I46: =IF(OR(ISBLANK(D46),ISBLANK(F46)),"Очікується","Завершено") -> Завершено | J46: =IF(OR(ISBLANK(D46),ISBLANK(F46)),"—",ABS(D46-F46)) -> 11
...

Sheet Группа 3
C1: № | D1: Игрок
A2: 12 | B2: 46287.832 | C2: 1 | D2: Котліна Віра Валеріївна | E2: 3 | F2: ТАК | G2: Члени родин ветеранів | J2: ТАК
A3: 33 | B3: 46294.262 | C3: 2 | D3: Концева Еліна Миколаївна | E3: 3 | F3: ТАК | G3: Члени родин ветеранів | J3: ТАК
A4: 34 | B4: 46294.878 | C4: 3 | D4: Папурова Антоніна Петрівна | E4: 3 | F4: ТАК | G4: Члени родин ветеранів | J4: ТАК
C5: 4 | D5: Крівонос Галина
A6: 8 | B6: 46286.674 | C6: 5 | D6: Катеринич Ірина Вікторівна | E6: 3 | F6: ТАК | G6: Члени родин ветеранів | J6: ТАК
A7: 9 | B7: 46286.756 | C7: 6 | D7: Ільїна Наталія Василівна | E7: 3 | F7: ТАК | G7: Ветерани без поранень | J7: ТАК
E191: 16
E192: 28
E193: 5
E195: 4
E197: 4 | F197: 14

Sheet Сетка Группа 3
B2: ТУРНІР З ПІКЛБОЛУ — ГРУПА 3 (ФОРМАТ «АМЕРИКАНО» — 6 МАТЧІВ)
B3: 1. СКЛАД УЧАСНИЦЬ | L3: 2. ПІДСУМКОВА ТАБЛИЦЯ ІНДИВІДУАЛЬНОГО РЕЙТИНГУ
B4: № | C4: Гравець (ПІБ) | D4: Коротке ім'я | L4: № | M4: Гравець | N4: Ігри | O4: В | P4: П | Q4: Очки (+) | R4: Очки (-) | S4: Різниця (±) | T4: Місце
B5: ='Группа 3'!C2 -> 1 | C5: ='Группа 3'!D2 -> Котліна Віра Валеріївна | D5: =IFERROR(__xludf.DUMMYFUNCTION("INDEX(SPLIT(C5, "" ""), 1) & "" "" & LEFT(INDEX(SPLIT(C5, "" ""), 2), 1) & ""."""),"Котліна В.") -> Котліна В. | L5: 1 | M5: =D5 -> Котліна В. | N5: =(ISNUMBER($D$14)*ISNUMBER($F$14))+(ISNUMBER($D$16)*ISNUMBER($F$16))+(ISNUMBER($D$17)*ISNUMBER($F$17))+(ISNUMBER($D$18)*ISNUMBER($F$18)) -> 4 | O5: =(ISNUMBER($D$14)*ISNUMBER($F$14)*($D$14>$F$14))+(ISNUMBER($D$16)*ISNUMBER($F$16)*($D$16>$F$16))+(ISNUMBER($D$17)*ISNUMBER($F$17)*($D$17>$F$17))+(ISNUMBER($D$18)*ISNUMBER($F$18)*($D$18>$F$18)) -> 2 | P5: =(ISNUMBER($D$14)*ISNUMBER($F$14)*($D$14<$F$14))+(ISNUMBER($D$16)*ISNUMBER($F$16)*($D$16<$F$16))+(ISNUMBER($D$17)*ISNUMBER($F$17)*($D$17<$F$17))+(ISNUMBER($D$18)*ISNUMBER($F$18)*($D$18<$F$18)) -> 2 | Q5: =(ISNUMBER($D$14)*$D$14)+(ISNUMBER($D$16)*$D$16)+(ISNUMBER($D$17)*$D$17)+(ISNUMBER($D$18)*$D$18) -> 25 | R5: =(ISNUMBER($F$14)*$F$14)+(ISNUMBER($F$16)*$F$16)+(ISNUMBER($F$17)*$F$17)+(ISNUMBER($F$18)*$F$18) -> 25 | S5: =Q5-R5 -> 0 | T5: =IF(SUM($N$5:$N$10)=0, "—", 1 + COUNTIFS($S$5:$S$10, ">"&S5) + COUNTIFS($S$5:$S$10, S5, $O$5:$O$10, ">"&O5) + COUNTIFS($S$5:$S$10, S5, $O$5:$O$10, O5, $Q$5:$Q$10, ">"&Q5)) -> 4
B6: ='Группа 3'!C3 -> 2 | C6: ='Группа 3'!D3 -> Концева Еліна Миколаївна | D6: =IFERROR(__xludf.DUMMYFUNCTION("INDEX(SPLIT(C6, "" ""), 1) & "" "" & LEFT(INDEX(SPLIT(C6, "" ""), 2), 1) & ""."""),"Концева Е.") -> Концева Е. | E6: 3 | L6: 2 | M6: =D6 -> Концева Е. | N6: =(ISNUMBER($D$15)*ISNUMBER($F$15))+(ISNUMBER($D$16)*ISNUMBER($F$16))+(ISNUMBER($D$17)*ISNUMBER($F$17))+(ISNUMBER($D$19)*ISNUMBER($F$19)) -> 4 | O6: =(ISNUMBER($D$15)*ISNUMBER($F$15)*($D$15>$F$15))+(ISNUMBER($D$16)*ISNUMBER($F$16)*($F$16>$D$16))+(ISNUMBER($D$17)*ISNUMBER($F$17)*($F$17>$D$17))+(ISNUMBER($D$19)*ISNUMBER($F$19)*($D$19>$F$19)) -> 2 | P6: =(ISNUMBER($D$15)*ISNUMBER($F$15)*($D$15<$F$15))+(ISNUMBER($D$16)*ISNUMBER($F$16)*($F$16<$D$16))+(ISNUMBER($D$17)*ISNUMBER($F$17)*($F$17<$D$17))+(ISNUMBER($D$19)*ISNUMBER($F$19)*($D$19<$F$19)) -> 2 | Q6: =(ISNUMBER($D$15)*$D$15)+(ISNUMBER($F$16)*$F$16)+(ISNUMBER($F$17)*$F$17)+(ISNUMBER($D$19)*$D$19) -> 30 | R6: =(ISNUMBER($F$15)*$F$15)+(ISNUMBER($D$16)*$D$16)+(ISNUMBER($D$17)*$D$17)+(ISNUMBER($F$19)*$F$19) -> 29 | S6: =Q6-R6 -> 1 | T6: =IF(SUM($N$5:$N$10)=0, "—", 1 + COUNTIFS($S$5:$S$10, ">"&S6) + COUNTIFS($S$5:$S$10, S6, $O$5:$O$10, ">"&O6) + COUNTIFS($S$5:$S$10, S6, $O$5:$O$10, O6, $Q$5:$Q$10, ">"&Q6)) -> 3
B7: ='Группа 3'!C4 -> 3 | C7: ='Группа 3'!D4 -> Папурова Антоніна Петрівна | D7: =IFERROR(__xludf.DUMMYFUNCTION("INDEX(SPLIT(C7, "" ""), 1) & "" "" & LEFT(INDEX(SPLIT(C7, "" ""), 2), 1) & ""."""),"Папурова А.") -> Папурова А. | L7: 3 | M7: =D7 -> Папурова А. | N7: =(ISNUMBER($D$14)*ISNUMBER($F$14))+(ISNUMBER($D$15)*ISNUMBER($F$15))+(ISNUMBER($D$17)*ISNUMBER($F$17))+(ISNUMBER($D$19)*ISNUMBER($F$19)) -> 4 | O7: =(ISNUMBER($D$14)*ISNUMBER($F$14)*($F$14>$D$14))+(ISNUMBER($D$15)*ISNUMBER($F$15)*($D$15>$F$15))+(ISNUMBER($D$17)*ISNUMBER($F$17)*($D$17>$F$17))+(ISNUMBER($D$19)*ISNUMBER($F$19)*($F$19>$D$19)) -> 1 | P7: =(ISNUMBER($D$14)*ISNUMBER($F$14)*($F$14<$D$14))+(ISNUMBER($D$15)*ISNUMBER($F$15)*($D$15<$F$15))+(ISNUMBER($D$17)*ISNUMBER($F$17)*($D$17<$F$17))+(ISNUMBER($D$19)*ISNUMBER($F$19)*($F$19<$D$19)) -> 3 | Q7: =(ISNUMBER($F$14)*$F$14)+(ISNUMBER($D$15)*$D$15)+(ISNUMBER($D$17)*$D$17)+(ISNUMBER($F$19)*$F$19) -> 24 | R7: =(ISNUMBER($D$14)*$D$14)+(ISNUMBER($F$15)*$F$15)+(ISNUMBER($F$17)*$F$17)+(ISNUMBER($D$19)*$D$19) -> 33 | S7: =Q7-R7 -> -9 | T7: =IF(SUM($N$5:$N$10)=0, "—", 1 + COUNTIFS($S$5:$S$10, ">"&S7) + COUNTIFS($S$5:$S$10, S7, $O$5:$O$10, ">"&O7) + COUNTIFS($S$5:$S$10, S7, $O$5:$O$10, O7, $Q$5:$Q$10, ">"&Q7)) -> 5
B8: ='Группа 3'!C5 -> 4 | C8: ='Группа 3'!D5 -> Крівонос Галина | D8: =IFERROR(__xludf.DUMMYFUNCTION("INDEX(SPLIT(C8, "" ""), 1) & "" "" & LEFT(INDEX(SPLIT(C8, "" ""), 2), 1) & ""."""),"Крівонос Г.") -> Крівонос Г. | E8: 1 | L8: 4 | M8: =D8 -> Крівонос Г. | N8: =(ISNUMBER($D$14)*ISNUMBER($F$14))+(ISNUMBER($D$15)*ISNUMBER($F$15))+(ISNUMBER($D$17)*ISNUMBER($F$17))+(ISNUMBER($D$18)*ISNUMBER($F$18)) -> 4 | O8: =(ISNUMBER($D$14)*ISNUMBER($F$14)*($F$14>$D$14))+(ISNUMBER($D$15)*ISNUMBER($F$15)*($F$15>$D$15))+(ISNUMBER($D$17)*ISNUMBER($F$17)*($F$17>$D$17))+(ISNUMBER($D$18)*ISNUMBER($F$18)*($D$18>$F$18)) -> 4 | P8: =(ISNUMBER($D$14)*ISNUMBER($F$14)*($F$14<$D$14))+(ISNUMBER($D$15)*ISNUMBER($F$15)*($F$15<$D$15))+(ISNUMBER($D$17)*ISNUMBER($F$17)*($F$17<$D$17))+(ISNUMBER($D$18)*ISNUMBER($F$18)*($D$18<$F$18)) -> 0 | Q8: =(ISNUMBER($F$14)*$F$14)+(ISNUMBER($F$15)*$F$15)+(ISNUMBER($F$17)*$F$17)+(ISNUMBER($D$18)*$D$18) -> 44 | R8: =(ISNUMBER($D$14)*$D$14)+(ISNUMBER($D$15)*$D$15)+(ISNUMBER($D$17)*$D$17)+(ISNUMBER($F$18)*$F$18) -> 10 | S8: =Q8-R8 -> 34 | T8: =IF(SUM($N$5:$N$10)=0, "—", 1 + COUNTIFS($S$5:$S$10, ">"&S8) + COUNTIFS($S$5:$S$10, S8, $O$5:$O$10, ">"&O8) + COUNTIFS($S$5:$S$10, S8, $O$5:$O$10, O8, $Q$5:$Q$10, ">"&Q8)) -> 1
B9: ='Группа 3'!C6 -> 5 | C9: ='Группа 3'!D6 -> Катеринич Ірина Вікторівна | D9: =IFERROR(__xludf.DUMMYFUNCTION("INDEX(SPLIT(C9, "" ""), 1) & "" "" & LEFT(INDEX(SPLIT(C9, "" ""), 2), 1) & ""."""),"Катеринич І.") -> Катеринич І. | E9: 2 | L9: 5 | M9: =D9 -> Катеринич І. | N9: =(ISNUMBER($D$15)*ISNUMBER($F$15))+(ISNUMBER($D$16)*ISNUMBER($F$16))+(ISNUMBER($D$18)*ISNUMBER($F$18))+(ISNUMBER($D$19)*ISNUMBER($F$19)) -> 4 | O9: =(ISNUMBER($D$15)*ISNUMBER($F$15)*($F$15>$D$15))+(ISNUMBER($D$16)*ISNUMBER($F$16)*($D$16>$F$16))+(ISNUMBER($D$18)*ISNUMBER($F$18)*($F$18>$D$18))+(ISNUMBER($D$19)*ISNUMBER($F$19)*($D$19>$F$19)) -> 3 | P9: =(ISNUMBER($D$15)*ISNUMBER($F$15)*($F$15<$D$15))+(ISNUMBER($D$16)*ISNUMBER($F$16)*($D$16<$F$16))+(ISNUMBER($D$18)*ISNUMBER($F$18)*($F$18<$D$18))+(ISNUMBER($D$19)*ISNUMBER($F$19)*($D$19<$F$19)) -> 1 | Q9: =(ISNUMBER($F$15)*$F$15)+(ISNUMBER($D$16)*$D$16)+(ISNUMBER($F$18)*$F$18)+(ISNUMBER($D$19)*$D$19) -> 34 | R9: =(ISNUMBER($D$15)*$D$15)+(ISNUMBER($F$16)*$F$16)+(ISNUMBER($D$18)*$D$18)+(ISNUMBER($F$19)*$F$19) -> 23 | S9: =Q9-R9 -> 11 | T9: =IF(SUM($N$5:$N$10)=0, "—", 1 + COUNTIFS($S$5:$S$10, ">"&S9) + COUNTIFS($S$5:$S$10, S9, $O$5:$O$10, ">"&O9) + COUNTIFS($S$5:$S$10, S9, $O$5:$O$10, O9, $Q$5:$Q$10, ">"&Q9)) -> 2
B10: ='Группа 3'!C7 -> 6 | C10: ='Группа 3'!D7 -> Ільїна Наталія Василівна | D10: =IFERROR(__xludf.DUMMYFUNCTION("INDEX(SPLIT(C10, "" ""), 1) & "" "" & LEFT(INDEX(SPLIT(C10, "" ""), 2), 1) & ""."""),"Ільїна Н.") -> Ільїна Н. | L10: 6 | M10: =D10 -> Ільїна Н. | N10: =(ISNUMBER($D$14)*ISNUMBER($F$14))+(ISNUMBER($D$16)*ISNUMBER($F$16))+(ISNUMBER($D$18)*ISNUMBER($F$18))+(ISNUMBER($D$19)*ISNUMBER($F$19)) -> 4 | O10: =(ISNUMBER($D$14)*ISNUMBER($F$14)*($D$14>$F$14))+(ISNUMBER($D$16)*ISNUMBER($F$16)*($F$16>$D$16))+(ISNUMBER($D$18)*ISNUMBER($F$18)*($F$18>$D$18))+(ISNUMBER($D$19)*ISNUMBER($F$19)*($F$19>$D$19)) -> 0 | P10: =(ISNUMBER($D$14)*ISNUMBER($F$14)*($D$14<$F$14))+(ISNUMBER($D$16)*ISNUMBER($F$16)*($F$16<$D$16))+(ISNUMBER($D$18)*ISNUMBER($F$18)*($F$18<$D$18))+(ISNUMBER($D$19)*ISNUMBER($F$19)*($F$19<$D$19)) -> 4 | Q10: =(ISNUMBER($D$14)*$D$14)+(ISNUMBER($F$16)*$F$16)+(ISNUMBER($F$18)*$F$18)+(ISNUMBER($F$19)*$F$19) -> 7 | R10: =(ISNUMBER($F$14)*$F$14)+(ISNUMBER($D$16)*$D$16)+(ISNUMBER($D$18)*$D$18)+(ISNUMBER($D$19)*$D$19) -> 44 | S10: =Q10-R10 -> -37 | T10: =IF(SUM($N$5:$N$10)=0, "—", 1 + COUNTIFS($S$5:$S$10, ">"&S10) + COUNTIFS($S$5:$S$10, S10, $O$5:$O$10, ">"&O10) + COUNTIFS($S$5:$S$10, S10, $O$5:$O$10, O10, $Q$5:$Q$10, ">"&Q10)) -> 6
B12: 3. РОЗКЛАД ТА РЕЗУЛЬТАТИ МАТЧІВ (АМЕРИКАНО — 6 МАТЧІВ)
B13: Матч | C13: Пара 1 | D13: Очки 1 | E13: : | F13: Очки 2 | G13: Пара 2 | H13: Відпочивають | I13: Переможець | J13: Різниця
B14: 1 | C14: =$D$5 & " / " & $D$10 -> Котліна В. / Ільїна Н. | D14: 0 | E14: : | F14: 11 | G14: =$D$7 & " / " & $D$8 -> Папурова А. / Крівонос Г. | H14: =$D$6 & ", " & $D$9 -> Концева Е., Катеринич І. | I14: =IF(OR(ISBLANK(D14), ISBLANK(F14)), "—", IF(D14>F14, C14, IF(F14>D14, G14, "Нічия"))) -> Папурова А. / Крівонос Г. | J14: =IF(OR(ISBLANK(D14), ISBLANK(F14)), "—", ABS(D14-F14)) -> 11
B15: 2 | C15: =$D$6 & " / " & $D$7 -> Концева Е. / Папурова А. | D15: 6 | E15: : | F15: 11 | G15: =$D$8 & " / " & $D$9 -> Крівонос Г. / Катеринич І. | H15: =$D$5 & ", " & $D$10 -> Котліна В., Ільїна Н. | I15: =IF(OR(ISBLANK(D15), ISBLANK(F15)), "—", IF(D15>F15, C15, IF(F15>D15, G15, "Нічия"))) -> Крівонос Г. / Катеринич І. | J15: =IF(OR(ISBLANK(D15), ISBLANK(F15)), "—", ABS(D15-F15)) -> 5
B16: 3 | C16: =$D$5 & " / " & $D$9 -> Котліна В. / Катеринич І. | D16: 11 | E16: : | F16: 2 | G16: =$D$6 & " / " & $D$10 -> Концева Е. / Ільїна Н. | H16: =$D$7 & ", " & $D$8 -> Папурова А., Крівонос Г. | I16: =IF(OR(ISBLANK(D16), ISBLANK(F16)), "—", IF(D16>F16, C16, IF(F16>D16, G16, "Нічия"))) -> Котліна В. / Катеринич І. | J16: =IF(OR(ISBLANK(D16), ISBLANK(F16)), "—", ABS(D16-F16)) -> 9
B17: 4 | C17: =$D$5 & " / " & $D$7 -> Котліна В. / Папурова А. | D17: 3 | E17: : | F17: 11 | G17: =$D$6 & " / " & $D$8 -> Концева Е. / Крівонос Г. | H17: =$D$9 & ", " & $D$10 -> Катеринич І., Ільїна Н. | I17: =IF(OR(ISBLANK(D17), ISBLANK(F17)), "—", IF(D17>F17, C17, IF(F17>D17, G17, "Нічия"))) -> Концева Е. / Крівонос Г. | J17: =IF(OR(ISBLANK(D17), ISBLANK(F17)), "—", ABS(D17-F17)) -> 8
B18: 5 | C18: =$D$5 & " / " & $D$8 -> Котліна В. / Крівонос Г. | D18: 11 | E18: : | F18: 1 | G18: =$D$9 & " / " & $D$10 -> Катеринич І. / Ільїна Н. | H18: =$D$6 & ", " & $D$7 -> Концева Е., Папурова А. | I18: =IF(OR(ISBLANK(D18), ISBLANK(F18)), "—", IF(D18>F18, C18, IF(F18>D18, G18, "Нічия"))) -> Котліна В. / Крівонос Г. | J18: =IF(OR(ISBLANK(D18), ISBLANK(F18)), "—", ABS(D18-F18)) -> 10
B19: 6 | C19: =$D$6 & " / " & $D$9 -> Концева Е. / Катеринич І. | D19: 11 | E19: : | F19: 4 | G19: =$D$7 & " / " & $D$10 -> Папурова А. / Ільїна Н. | H19: =$D$5 & ", " & $D$8 -> Котліна В., Крівонос Г. | I19: =IF(OR(ISBLANK(D19), ISBLANK(F19)), "—", IF(D19>F19, C19, IF(F19>D19, G19, "Нічия"))) -> Концева Е. / Катеринич І. | J19: =IF(OR(ISBLANK(D19), ISBLANK(F19)), "—", ABS(D19-F19)) -> 7
B20: * Рахунок матчів вводиться у стовпчики «Очки 1» та «Очки 2». Переможець та різниця розраховуються автоматично.
